Workbook

Sheet Instructions
A1: Monthly Budget Tracker — Instructions & Monthly Workflow
A3: A single-ledger cash-flow tracker. You record every income, expense and one-off item once on the Entries tab; the Monthly Summary and Dashboard rebuild themselves. This sheet is the manual — start with the checklist, details follow.
A5: THE TABS
A6: You edit three tabs: Entries (the ledger) · Budgets (your plan) · Categories (the master list).
A7: Read-only, automatic: Monthly Summary · Dashboard. Never type into these — they recalculate from the three above.
A8: Tool files that live in the same folder as this workbook: categorize_expenses.py · rules.csv (used in Step 2).
A10: YOUR MONTHLY ROUTINE — AT A GLANCE
A11: [ ] 1. Gather this month’s bank statement (.xlsx) and any credit-card bills you paid (.pdf).
A12: [ ] 2. Produce the categorised draft (send the files to Claude, or run the script).
A13: [ ] 3. Open the draft’s Validation tab (status must not be FAIL); fix amber flags, confirm categories, teach any new merchants.
A14: [ ] 4. Paste the draft’s "Entries draft" rows into the Entries tab.
A15: [ ] 5. (Nothing to do — Monthly Summary fills in the new month automatically.)
... A71: The bank parser is tuned to the UOB One Account layout and the bill parser to the UOB card format. A different bank or card bill needs a small parser addition — add a matching BANK_FORMATS / CARD_FORMATS entry (see the TEMPLATE blocks).

Sheet Dashboard
A1: Monthly Budget Tracker — Dashboard
A2: Everything updates from the Entries ledger. This sheet is locked (read-only).
A4: Latest month | C4: Cash saved (operating, cumulative) | E4: Rolling savings ratio (12m) | G4: Avg monthly spend (12m)
A5: =TEXT(LOOKUP(2,1/('Monthly Summary'!$C$2:$C$400<>""),'Monthly Summary'!$A$2:$A$400),"mmm yyyy") | C5: =LOOKUP(2,1/('Monthly Summary'!$C$2:$C$400<>""),'Monthly Summary'!$J$2:$J$400) | E5: =LOOKUP(2,1/('Monthly Summary'!$C$2:$C$400<>""),'Monthly Summary'!$M$2:$M$400) | G5: =LOOKUP(2,1/('Monthly Summary'!$C$2:$C$400<>""),'Monthly Summary'!$L$2:$L$400)
A39: Budget vs Actual — latest month (helper for chart)
A40: Category | B40: Actual | C40: Budget | E40: Latest month: | F40: =LOOKUP(2,1/('Monthly Summary'!$C$2:$C$400<>""),'Monthly Summary'!$A$2:$A$400)
A41: Daily Food | B41: =SUMIFS(Entries!$D$2:$D$5000,Entries!$C$2:$C$5000,"Actual",Entries!$A$2:$A$5000,$F$40,Entries!$B$2:$B$5000,$A41) | C41: =IFERROR(LOOKUP(2,1/((Budgets!$A$2:$A$200=$A41)*(Budgets!$B$2:$B$200<=$F$40)),Budgets!$C$2:$C$200),0)
A42: Transport | B42: =SUMIFS(Entries!$D$2:$D$5000,Entries!$C$2:$C$5000,"Actual",Entries!$A$2:$A$5000,$F$40,Entries!$B$2:$B$5000,$A42) | C42: =IFERROR(LOOKUP(2,1/((Budgets!$A$2:$A$200=$A42)*(Budgets!$B$2:$B$200<=$F$40)),Budgets!$C$2:$C$200),0)
A43: Credit Card | B43: =SUMIFS(Entries!$D$2:$D$5000,Entries!$C$2:$C$5000,"Actual",Entries!$A$2:$A$5000,$F$40,Entries!$B$2:$B$5000,$A43) | C43: =IFERROR(LOOKUP(2,1/((Budgets!$A$2:$A$200=$A43)*(Budgets!$B$2:$B$200<=$F$40)),Budgets!$C$2:$C$200),0)
A44: Household | B44: =SUMIFS(Entries!$D$2:$D$5000,Entries!$C$2:$C$5000,"Actual",Entries!$A$2:$A$5000,$F$40,Entries!$B$2:$B$5000,$A44) | C44: =IFERROR(LOOKUP(2,1/((Budgets!$A$2:$A$200=$A44)*(Budgets!$B$2:$B$200<=$F$40)),Budgets!$C$2:$C$200),0)
A45: Tax | B45: =SUMIFS(Entries!$D$2:$D$5000,Entries!$C$2:$C$5000,"Actual",Entries!$A$2:$A$5000,$F$40,Entries!$B$2:$B$5000,$A45) | C45: =IFERROR(LOOKUP(2,1/((Budgets!$A$2:$A$200=$A45)*(Budgets!$B$2:$B$200<=$F$40)),Budgets!$C$2:$C$200),0)
A46: Savings for holiday | B46: =SUMIFS(Entries!$D$2:$D$5000,Entries!$C$2:$C$5000,"Actual",Entries!$A$2:$A$5000,$F$40,Entries!$B$2:$B$5000,$A46) | C46: =IFERROR(LOOKUP(2,1/((Budgets!$A$2:$A$200=$A46)*(Budgets!$B$2:$B$200<=$F$40)),Budgets!$C$2:$C$200),0)
A47: Bills | B47: =SUMIFS(Entries!$D$2:$D$5000,Entries!$C$2:$C$5000,"Actual",Entries!$A$2:$A$5000,$F$40,Entries!$B$2:$B$5000,$A47) | C47: =IFERROR(LOOKUP(2,1/((Budgets!$A$2:$A$200=$A47)*(Budgets!$B$2:$B$200<=$F$40)),Budgets!$C$2:$C$200),0)
A48: Insurance | B48: =SUMIFS(Entries!$D$2:$D$5000,Entries!$C$2:$C$5000,"Actual",Entries!$A$2:$A$5000,$F$40,Entries!$B$2:$B$5000,$A48) | C48: =IFERROR(LOOKUP(2,1/((Budgets!$A$2:$A$200=$A48)*(Budgets!$B$2:$B$200<=$F$40)),Budgets!$C$2:$C$200),0)
A49: Donation | B49: =SUMIFS(Entries!$D$2:$D$5000,Entries!$C$2:$C$5000,"Actual",Entries!$A$2:$A$5000,$F$40,Entries!$B$2:$B$5000,$A49) | C49: =IFERROR(LOOKUP(2,1/((Budgets!$A$2:$A$200=$A49)*(Budgets!$B$2:$B$200<=$F$40)),Budgets!$C$2:$C$200),0)
A50: Groceries | B50: =SUMIFS(Entries!$D$2:$D$5000,Entries!$C$2:$C$5000,"Actual",Entries!$A$2:$A$5000,$F$40,Entries!$B$2:$B$5000,$A50) | C50: =IFERROR(LOOKUP(2,1/((Budgets!$A$2:$A$200=$A50)*(Budgets!$B$2:$B$200<=$F$40)),Budgets!$C$2:$C$200),0)
A51: Subscriptions | B51: =SUMIFS(Entries!$D$2:$D$5000,Entries!$C$2:$C$5000,"Actual",Entries!$A$2:$A$5000,$F$40,Entries!$B$2:$B$5000,$A51) | C51: =IFERROR(LOOKUP(2,1/((Budgets!$A$2:$A$200=$A51)*(Budgets!$B$2:$B$200<=$F$40)),Budgets!$C$2:$C$200),0)
A52: Shopping | B52: =SUMIFS(Entries!$D$2:$D$5000,Entries!$C$2:$C$5000,"Actual",Entries!$A$2:$A$5000,$F$40,Entries!$B$2:$B$5000,$A52) | C52: =IFERROR(LOOKUP(2,1/((Budgets!$A$2:$A$200=$A52)*(Budgets!$B$2:$B$200<=$F$40)),Budgets!$C$2:$C$200),0)
... A56: Household Help | B56: =SUMIFS(Entries!$D$2:$D$5000,Entries!$C$2:$C$5000,"Actual",Entries!$A$2:$A$5000,$F$40,Entries!$B$2:$B$5000,$A56) | C56: =IFERROR(LOOKUP(2,1/((Budgets!$A$2:$A$200=$A56)*(Budgets!$B$2:$B$200<=$F$40)),Budgets!$C$2:$C$200),0)

Sheet Monthly Summary
A1: Month | B1: Total Income | C1: Total Actual | D1: Total One-off | E1: Total Spend | F1: Total Budget | G1: Net Cash | H1: Cumulative Cash | I1: Capital Outflow | J1: Cumulative (operating) | K1: Rolling Income 12m | L1: Rolling Spend 12m | M1: Rolling Savings Ratio | O1: =IFERROR(INDEX(Categories!$A$2:$A$200,MATCH(1,Categories!$F$2:$F$200,0)),"") | P1: =IFERROR(INDEX(Categories!$A$2:$A$200,MATCH(2,Categories!$F$2:$F$200,0)),"") | Q1: =IFERROR(INDEX(Categories!$A$2:$A$200,MATCH(3,Categories!$F$2:$F$200,0)),"") | R1: =IFERROR(INDEX(Categories!$A$2:$A$200,MATCH(4,Categories!$F$2:$F$200,0)),"") | S1: =IFERROR(INDEX(Categories!$A$2:$A$200,MATCH(5,Categories!$F$2:$F$200,0)),"") | T1: =IFERROR(INDEX(Categories!$A$2:$A$200,MATCH(6,Categories!$F$2:$F$200,0)),"") | U1: =IFERROR(INDEX(Categories!$A$2:$A$200,MATCH(7,Categories!$F$2:$F$200,0)),"") | V1: =IFERROR(INDEX(Categories!$A$2:$A$200,MATCH(8,Categories!$F$2:$F$200,0)),"") | W1: =IFERROR(INDEX(Categories!$A$2:$A$200,MATCH(9,Categories!$F$2:$F$200,0)),"") | X1: =IFERROR(INDEX(Categories!$A$2:$A$200,MATCH(10,Categories!$F$2:$F$200,0)),"") | Y1: =IFERROR(INDEX(Categories!$A$2:$A$200,MATCH(11,Categories!$F$2:$F$200,0)),"") | Z1: =IFERROR(INDEX(Categories!$A$2:$A$200,MATCH(12,Categories!$F$2:$F$200,0)),"") | AA1: =IFERROR(INDEX(Categories!$A$2:$A$200,MATCH(13,Categories!$F$2:$F$200,0)),"") | AB1: =IFERROR(INDEX(Categories!$A$2:$A$200,MATCH(14,Categories!$F$2:$F$200,0)),"") | AC1: =IFERROR(INDEX(Categories!$A$2:$A$200,MATCH(15,Categories!$F$2:$F$200,0)),"") | AD1: =IFERROR(INDEX(Categories!$A$2:$A$200,MATCH(16,Categories!$F$2:$F$200,0)),"") | AE1: =IFERROR(INDEX(Categories!$A$2:$A$200,MATCH(17,Categories!$F$2:$F$200,0)),"") | AF1: =IFERROR(INDEX(Categories!$A$2:$A$200,MATCH(18,Categories!$F$2:$F$200,0)),"") | AG1: =IFERROR(INDEX(Categories!$A$2:$A$200,MATCH(19,Categories!$F$2:$F$200,0)),"") | AH1: =IFERROR(INDEX(Categories!$A$2:$A$200,MATCH(20,Categories!$F$2:$F$200,0)),"") | AJ1: =O$1 | AK1: =P$1 | AL1: =Q$1 | AM1: =R$1 | AN1: =S$1 | AO1: =T$1 | AP1: =U$1 | AQ1: =V$1 | ... BC1: =AH$1 | BE1: _active
A2: 39448 | B2: =IF($BE2=0,NA(),SUMIFS(Entries!$D$2:$D$5000,Entries!$C$2:$C$5000,"Income",Entries!$A$2:$A$5000,$A2)) | C2: =IF($BE2=0,"",SUMIFS(Entries!$D$2:$D$5000,Entries!$C$2:$C$5000,"Actual",Entries!$A$2:$A$5000,$A2)) | D2: =IF($BE2=0,"",SUMIFS(Entries!$D$2:$D$5000,Entries!$C$2:$C$5000,"One-off",Entries!$A$2:$A$5000,$A2)) | E2: =IF($BE2=0,NA(),C2+D2) | F2: =IF($BE2=0,"",SUM(AJ2:BC2)) | G2: =IF($BE2=0,"",B2-E2) | H2: =IF($BE2=0,"",SUM($G$2:G2)) | I2: =IF($BE2=0,"",SUMIFS(Entries!$F$2:$F$5000,Entries!$A$2:$A$5000,$A2)) | J2: =IF($BE2=0,NA(),H2+SUM($I$2:I2)) | K2: ="" | L2: ="" | M2: =NA() | O2: =IF(OR(O$1="",$BE2=0),"",SUMIFS(Entries!$D$2:$D$5000,Entries!$C$2:$C$5000,"Actual",Entries!$A$2:$A$5000,$A2,Entries!$B$2:$B$5000,O$1)) | P2: =IF(OR(P$1="",$BE2=0),"",SUMIFS(Entries!$D$2:$D$5000,Entries!$C$2:$C$5000,"Actual",Entries!$A$2:$A$5000,$A2,Entries!$B$2:$B$5000,P$1)) | Q2: =IF(OR(Q$1="",$BE2=0),"",SUMIFS(Entries!$D$2:$D$5000,Entries!$C$2:$C$5000,"Actual",Entries!$A$2:$A$5000,$A2,Entries!$B$2:$B$5000,Q$1)) | R2: =IF(OR(R$1="",$BE2=0),"",SUMIFS(Entries!$D$2:$D$5000,Entries!$C$2:$C$5000,"Actual",Entries!$A$2:$A$5000,$A2,Entries!$B$2:$B$5000,R$1)) | S2: =IF(OR(S$1="",$BE2=0),"",SUMIFS(Entries!$D$2:$D$5000,Entries!$C$2:$C$5000,"Actual",Entries!$A$2:$A$5000,$A2,Entries!$B$2:$B$5000,S$1)) | T2: =IF(OR(T$1="",$BE2=0),"",SUMIFS(Entries!$D$2:$D$5000,Entries!$C$2:$C$5000,"Actual",Entries!$A$2:$A$5000,$A2,Entries!$B$2:$B$5000,T$1)) | U2: =IF(OR(U$1="",$BE2=0),"",SUMIFS(Entries!$D$2:$D$5000,Entries!$C$2:$C$5000,"Actual",Entries!$A$2:$A$5000,$A2,Entries!$B$2:$B$5000,U$1)) | V2: =IF(OR(V$1="",$BE2=0),"",SUMIFS(Entries!$D$2:$D$5000,Entries!$C$2:$C$5000,"Actual",Entries!$A$2:$A$5000,$A2,Entries!$B$2:$B$5000,V$1)) | ... AH2: =IF(OR(AH$1="",$BE2=0),"",SUMIFS(Entries!$D$2:$D$5000,Entries!$C$2:$C$5000,"Actual",Entries!$A$2:$A$5000,$A2,Entries!$B$2:$B$5000,AH$1)) | AJ2: =IF(OR(AJ$1="",$BE2=0),"",IFERROR(LOOKUP(2,1/((Budgets!$A$2:$A$200=AJ$1)*(Budgets!$B$2:$B$200<=$A2)),Budgets!$C$2:$C$200),0)) | AK2: =IF(OR(AK$1="",$BE2=0),"",IFERROR(LOOKUP(2,1/((Budgets!$A$2:$A$200=AK$1)*(Budgets!$B$2:$B$200<=$A2)),Budgets!$C$2:$C$200),0)) | AL2: =IF(OR(AL$1="",$BE2=0),"",IFERROR(LOOKUP(2,1/((Budgets!$A$2:$A$200=AL$1)*(Budgets!$B$2:$B$200<=$A2)),Budgets!$C$2:$C$200),0)) | AM2: =IF(OR(AM$1="",$BE2=0),"",IFERROR(LOOKUP(2,1/((Budgets!$A$2:$A$200=AM$1)*(Budgets!$B$2:$B$200<=$A2)),Budgets!$C$2:$C$200),0)) | AN2: =IF(OR(AN$1="",$BE2=0),"",IFERROR(LOOKUP(2,1/((Budgets!$A$2:$A$200=AN$1)*(Budgets!$B$2:$B$200<=$A2)),Budgets!$C$2:$C$200),0)) | AO2: =IF(OR(AO$1="",$BE2=0),"",IFERROR(LOOKUP(2,1/((Budgets!$A$2:$A$200=AO$1)*(Budgets!$B$2:$B$200<=$A2)),Budgets!$C$2:$C$200),0)) | AP2: =IF(OR(AP$1="",$BE2=0),"",IFERROR(LOOKUP(2,1/((Budgets!$A$2:$A$200=AP$1)*(Budgets!$B$2:$B$200<=$A2)),Budgets!$C$2:$C$200),0)) | AQ2: =IF(OR(AQ$1="",$BE2=0),"",IFERROR(LOOKUP(2,1/((Budgets!$A$2:$A$200=AQ$1)*(Budgets!$B$2:$B$200<=$A2)),Budgets!$C$2:$C$200),0)) | ... BC2: =IF(OR(BC$1="",$BE2=0),"",IFERROR(LOOKUP(2,1/((Budgets!$A$2:$A$200=BC$1)*(Budgets!$B$2:$B$200<=$A2)),Budgets!$C$2:$C$200),0)) | BE2: =COUNTIFS(Entries!$A$2:$A$5000,$A2)
A3: 39479 | B3: =IF($BE3=0,NA(),SUMIFS(Entries!$D$2:$D$5000,Entries!$C$2:$C$5000,"Income",Entries!$A$2:$A$5000,$A3)) | C3: =IF($BE3=0,"",SUMIFS(Entries!$D$2:$D$5000,Entries!$C$2:$C$5000,"Actual",Entries!$A$2:$A$5000,$A3)) | D3: =IF($BE3=0,"",SUMIFS(Entries!$D$2:$D$5000,Entries!$C$2:$C$5000,"One-off",Entries!$A$2:$A$5000,$A3)) | E3: =IF($BE3=0,NA(),C3+D3) | F3: =IF($BE3=0,"",SUM(AJ3:BC3)) | G3: =IF($BE3=0,"",B3-E3) | H3: =IF($BE3=0,"",SUM($G$2:G3)) | I3: =IF($BE3=0,"",SUMIFS(Entries!$F$2:$F$5000,Entries!$A$2:$A$5000,$A3)) | J3: =IF($BE3=0,NA(),H3+SUM($I$2:I3)) | K3: ="" | L3: ="" | M3: =NA() | O3: =IF(OR(O$1="",$BE3=0),"",SUMIFS(Entries!$D$2:$D$5000,Entries!$C$2:$C$5000,"Actual",Entries!$A$2:$A$5000,$A3,Entries!$B$2:$B$5000,O$1)) | P3: =IF(OR(P$1="",$BE3=0),"",SUMIFS(Entries!$D$2:$D$5000,Entries!$C$2:$C$5000,"Actual",Entries!$A$2:$A$5000,$A3,Entries!$B$2:$B$5000,P$1)) | Q3: =IF(OR(Q$1="",$BE3=0),"",SUMIFS(Entries!$D$2:$D$5000,Entries!$C$2:$C$5000,"Actual",Entries!$A$2:$A$5000,$A3,Entries!$B$2:$B$5000,Q$1)) | R3: =IF(OR(R$1="",$BE3=0),"",SUMIFS(Entries!$D$2:$D$5000,Entries!$C$2:$C$5000,"Actual",Entries!$A$2:$A$5000,$A3,Entries!$B$2:$B$5000,R$1)) | S3: =IF(OR(S$1="",$BE3=0),"",SUMIFS(Entries!$D$2:$D$5000,Entries!$C$2:$C$5000,"Actual",Entries!$A$2:$A$5000,$A3,Entries!$B$2:$B$5000,S$1)) | T3: =IF(OR(T$1="",$BE3=0),"",SUMIFS(Entries!$D$2:$D$5000,Entries!$C$2:$C$5000,"Actual",Entries!$A$2:$A$5000,$A3,Entries!$B$2:$B$5000,T$1)) | U3: =IF(OR(U$1="",$BE3=0),"",SUMIFS(Entries!$D$2:$D$5000,Entries!$C$2:$C$5000,"Actual",Entries!$A$2:$A$5000,$A3,Entries!$B$2:$B$5000,U$1)) | V3: =IF(OR(V$1="",$BE3=0),"",SUMIFS(Entries!$D$2:$D$5000,Entries!$C$2:$C$5000,"Actual",Entries!$A$2:$A$5000,$A3,Entries!$B$2:$B$5000,V$1)) | ... AH3: =IF(OR(AH$1="",$BE3=0),"",SUMIFS(Entries!$D$2:$D$5000,Entries!$C$2:$C$5000,"Actual",Entries!$A$2:$A$5000,$A3,Entries!$B$2:$B$5000,AH$1)) | AJ3: =IF(OR(AJ$1="",$BE3=0),"",IFERROR(LOOKUP(2,1/((Budgets!$A$2:$A$200=AJ$1)*(Budgets!$B$2:$B$200<=$A3)),Budgets!$C$2:$C$200),0)) | AK3: =IF(OR(AK$1="",$BE3=0),"",IFERROR(LOOKUP(2,1/((Budgets!$A$2:$A$200=AK$1)*(Budgets!$B$2:$B$200<=$A3)),Budgets!$C$2:$C$200),0)) | AL3: =IF(OR(AL$1="",$BE3=0),"",IFERROR(LOOKUP(2,1/((Budgets!$A$2:$A$200=AL$1)*(Budgets!$B$2:$B$200<=$A3)),Budgets!$C$2:$C$200),0)) | AM3: =IF(OR(AM$1="",$BE3=0),"",IFERROR(LOOKUP(2,1/((Budgets!$A$2:$A$200=AM$1)*(Budgets!$B$2:$B$200<=$A3)),Budgets!$C$2:$C$200),0)) | AN3: =IF(OR(AN$1="",$BE3=0),"",IFERROR(LOOKUP(2,1/((Budgets!$A$2:$A$200=AN$1)*(Budgets!$B$2:$B$200<=$A3)),Budgets!$C$2:$C$200),0)) | AO3: =IF(OR(AO$1="",$BE3=0),"",IFERROR(LOOKUP(2,1/((Budgets!$A$2:$A$200=AO$1)*(Budgets!$B$2:$B$200<=$A3)),Budgets!$C$2:$C$200),0)) | AP3: =IF(OR(AP$1="",$BE3=0),"",IFERROR(LOOKUP(2,1/((Budgets!$A$2:$A$200=AP$1)*(Budgets!$B$2:$B$200<=$A3)),Budgets!$C$2:$C$200),0)) | AQ3: =IF(OR(AQ$1="",$BE3=0),"",IFERROR(LOOKUP(2,1/((Budgets!$A$2:$A$200=AQ$1)*(Budgets!$B$2:$B$200<=$A3)),Budgets!$C$2:$C$200),0)) | ... BC3: =IF(OR(BC$1="",$BE3=0),"",IFERROR(LOOKUP(2,1/((Budgets!$A$2:$A$200=BC$1)*(Budgets!$B$2:$B$200<=$A3)),Budgets!$C$2:$C$200),0)) | BE3: =COUNTIFS(Entries!$A$2:$A$5000,$A3)
A4: 39508 | B4: =IF($BE4=0,NA(),SUMIFS(Entries!$D$2:$D$5000,Entries!$C$2:$C$5000,"Income",Entries!$A$2:$A$5000,$A4)) | C4: =IF($BE4=0,"",SUMIFS(Entries!$D$2:$D$5000,Entries!$C$2:$C$5000,"Actual",Entries!$A$2:$A$5000,$A4)) | D4: =IF($BE4=0,"",SUMIFS(Entries!$D$2:$D$5000,Entries!$C$2:$C$5000,"One-off",Entries!$A$2:$A$5000,$A4)) | E4: =IF($BE4=0,NA(),C4+D4) | F4: =IF($BE4=0,"",SUM(AJ4:BC4)) | G4: =IF($BE4=0,"",B4-E4) | H4: =IF($BE4=0,"",SUM($G$2:G4)) | I4: =IF($BE4=0,"",SUMIFS(Entries!$F$2:$F$5000,Entries!$A$2:$A$5000,$A4)) | J4: =IF($BE4=0,NA(),H4+SUM($I$2:I4)) | K4: ="" | L4: ="" | M4: =NA() | O4: =IF(OR(O$1="",$BE4=0),"",SUMIFS(Entries!$D$2:$D$5000,Entries!$C$2:$C$5000,"Actual",Entries!$A$2:$A$5000,$A4,Entries!$B$2:$B$5000,O$1)) | P4: =IF(OR(P$1="",$BE4=0),"",SUMIFS(Entries!$D$2:$D$5000,Entries!$C$2:$C$5000,"Actual",Entries!$A$2:$A$5000,$A4,Entries!$B$2:$B$5000,P$1)) | Q4: =IF(OR(Q$1="",$BE4=0),"",SUMIFS(Entries!$D$2:$D$5000,Entries!$C$2:$C$5000,"Actual",Entries!$A$2:$A$5000,$A4,Entries!$B$2:$B$5000,Q$1)) | R4: =IF(OR(R$1="",$BE4=0),"",SUMIFS(Entries!$D$2:$D$5000,Entries!$C$2:$C$5000,"Actual",Entries!$A$2:$A$5000,$A4,Entries!$B$2:$B$5000,R$1)) | S4: =IF(OR(S$1="",$BE4=0),"",SUMIFS(Entries!$D$2:$D$5000,Entries!$C$2:$C$5000,"Actual",Entries!$A$2:$A$5000,$A4,Entries!$B$2:$B$5000,S$1)) | T4: =IF(OR(T$1="",$BE4=0),"",SUMIFS(Entries!$D$2:$D$5000,Entries!$C$2:$C$5000,"Actual",Entries!$A$2:$A$5000,$A4,Entries!$B$2:$B$5000,T$1)) | U4: =IF(OR(U$1="",$BE4=0),"",SUMIFS(Entries!$D$2:$D$5000,Entries!$C$2:$C$5000,"Actual",Entries!$A$2:$A$5000,$A4,Entries!$B$2:$B$5000,U$1)) | V4: =IF(OR(V$1="",$BE4=0),"",SUMIFS(Entries!$D$2:$D$5000,Entries!$C$2:$C$5000,"Actual",Entries!$A$2:$A$5000,$A4,Entries!$B$2:$B$5000,V$1)) | ... AH4: =IF(OR(AH$1="",$BE4=0),"",SUMIFS(Entries!$D$2:$D$5000,Entries!$C$2:$C$5000,"Actual",Entries!$A$2:$A$5000,$A4,Entries!$B$2:$B$5000,AH$1)) | AJ4: =IF(OR(AJ$1="",$BE4=0),"",IFERROR(LOOKUP(2,1/((Budgets!$A$2:$A$200=AJ$1)*(Budgets!$B$2:$B$200<=$A4)),Budgets!$C$2:$C$200),0)) | AK4: =IF(OR(AK$1="",$BE4=0),"",IFERROR(LOOKUP(2,1/((Budgets!$A$2:$A$200=AK$1)*(Budgets!$B$2:$B$200<=$A4)),Budgets!$C$2:$C$200),0)) | AL4: =IF(OR(AL$1="",$BE4=0),"",IFERROR(LOOKUP(2,1/((Budgets!$A$2:$A$200=AL$1)*(Budgets!$B$2:$B$200<=$A4)),Budgets!$C$2:$C$200),0)) | AM4: =IF(OR(AM$1="",$BE4=0),"",IFERROR(LOOKUP(2,1/((Budgets!$A$2:$A$200=AM$1)*(Budgets!$B$2:$B$200<=$A4)),Budgets!$C$2:$C$200),0)) | AN4: =IF(OR(AN$1="",$BE4=0),"",IFERROR(LOOKUP(2,1/((Budgets!$A$2:$A$200=AN$1)*(Budgets!$B$2:$B$200<=$A4)),Budgets!$C$2:$C$200),0)) | AO4: =IF(OR(AO$1="",$BE4=0),"",IFERROR(LOOKUP(2,1/((Budgets!$A$2:$A$200=AO$1)*(Budgets!$B$2:$B$200<=$A4)),Budgets!$C$2:$C$200),0)) | AP4: =IF(OR(AP$1="",$BE4=0),"",IFERROR(LOOKUP(2,1/((Budgets!$A$2:$A$200=AP$1)*(Budgets!$B$2:$B$200<=$A4)),Budgets!$C$2:$C$200),0)) | AQ4: =IF(OR(AQ$1="",$BE4=0),"",IFERROR(LOOKUP(2,1/((Budgets!$A$2:$A$200=AQ$1)*(Budgets!$B$2:$B$200<=$A4)),Budgets!$C$2:$C$200),0)) | ... BC4: =IF(OR(BC$1="",$BE4=0),"",IFERROR(LOOKUP(2,1/((Budgets!$A$2:$A$200=BC$1)*(Budgets!$B$2:$B$200<=$A4)),Budgets!$C$2:$C$200),0)) | BE4: =COUNTIFS(Entries!$A$2:$A$5000,$A4)
A5: 39539 | B5: =IF($BE5=0,NA(),SUMIFS(Entries!$D$2:$D$5000,Entries!$C$2:$C$5000,"Income",Entries!$A$2:$A$5000,$A5)) | C5: =IF($BE5=0,"",SUMIFS(Entries!$D$2:$D$5000,Entries!$C$2:$C$5000,"Actual",Entries!$A$2:$A$5000,$A5)) | D5: =IF($BE5=0,"",SUMIFS(Entries!$D$2:$D$5000,Entries!$C$2:$C$5000,"One-off",Entries!$A$2:$A$5000,$A5)) | E5: =IF($BE5=0,NA(),C5+D5) | F5: =IF($BE5=0,"",SUM(AJ5:BC5)) | G5: =IF($BE5=0,"",B5-E5) | H5: =IF($BE5=0,"",SUM($G$2:G5)) | I5: =IF($BE5=0,"",SUMIFS(Entries!$F$2:$F$5000,Entries!$A$2:$A$5000,$A5)) | J5: =IF($BE5=0,NA(),H5+SUM($I$2:I5)) | K5: ="" | L5: ="" | M5: =NA() | O5: =IF(OR(O$1="",$BE5=0),"",SUMIFS(Entries!$D$2:$D$5000,Entries!$C$2:$C$5000,"Actual",Entries!$A$2:$A$5000,$A5,Entries!$B$2:$B$5000,O$1)) | P5: =IF(OR(P$1="",$BE5=0),"",SUMIFS(Entries!$D$2:$D$5000,Entries!$C$2:$C$5000,"Actual",Entries!$A$2:$A$5000,$A5,Entries!$B$2:$B$5000,P$1)) | Q5: =IF(OR(Q$1="",$BE5=0),"",SUMIFS(Entries!$D$2:$D$5000,Entries!$C$2:$C$5000,"Actual",Entries!$A$2:$A$5000,$A5,Entries!$B$2:$B$5000,Q$1)) | R5: =IF(OR(R$1="",$BE5=0),"",SUMIFS(Entries!$D$2:$D$5000,Entries!$C$2:$C$5000,"Actual",Entries!$A$2:$A$5000,$A5,Entries!$B$2:$B$5000,R$1)) | S5: =IF(OR(S$1="",$BE5=0),"",SUMIFS(Entries!$D$2:$D$5000,Entries!$C$2:$C$5000,"Actual",Entries!$A$2:$A$5000,$A5,Entries!$B$2:$B$5000,S$1)) | T5: =IF(OR(T$1="",$BE5=0),"",SUMIFS(Entries!$D$2:$D$5000,Entries!$C$2:$C$5000,"Actual",Entries!$A$2:$A$5000,$A5,Entries!$B$2:$B$5000,T$1)) | U5: =IF(OR(U$1="",$BE5=0),"",SUMIFS(Entries!$D$2:$D$5000,Entries!$C$2:$C$5000,"Actual",Entries!$A$2:$A$5000,$A5,Entries!$B$2:$B$5000,U$1)) | V5: =IF(OR(V$1="",$BE5=0),"",SUMIFS(Entries!$D$2:$D$5000,Entries!$C$2:$C$5000,"Actual",Entries!$A$2:$A$5000,$A5,Entries!$B$2:$B$5000,V$1)) | ... AH5: =IF(OR(AH$1="",$BE5=0),"",SUMIFS(Entries!$D$2:$D$5000,Entries!$C$2:$C$5000,"Actual",Entries!$A$2:$A$5000,$A5,Entries!$B$2:$B$5000,AH$1)) | AJ5: =IF(OR(AJ$1="",$BE5=0),"",IFERROR(LOOKUP(2,1/((Budgets!$A$2:$A$200=AJ$1)*(Budgets!$B$2:$B$200<=$A5)),Budgets!$C$2:$C$200),0)) | AK5: =IF(OR(AK$1="",$BE5=0),"",IFERROR(LOOKUP(2,1/((Budgets!$A$2:$A$200=AK$1)*(Budgets!$B$2:$B$200<=$A5)),Budgets!$C$2:$C$200),0)) | AL5: =IF(OR(AL$1="",$BE5=0),"",IFERROR(LOOKUP(2,1/((Budgets!$A$2:$A$200=AL$1)*(Budgets!$B$2:$B$200<=$A5)),Budgets!$C$2:$C$200),0)) | AM5: =IF(OR(AM$1="",$BE5=0),"",IFERROR(LOOKUP(2,1/((Budgets!$A$2:$A$200=AM$1)*(Budgets!$B$2:$B$200<=$A5)),Budgets!$C$2:$C$200),0)) | AN5: =IF(OR(AN$1="",$BE5=0),"",IFERROR(LOOKUP(2,1/((Budgets!$A$2:$A$200=AN$1)*(Budgets!$B$2:$B$200<=$A5)),Budgets!$C$2:$C$200),0)) | AO5: =IF(OR(AO$1="",$BE5=0),"",IFERROR(LOOKUP(2,1/((Budgets!$A$2:$A$200=AO$1)*(Budgets!$B$2:$B$200<=$A5)),Budgets!$C$2:$C$200),0)) | AP5: =IF(OR(AP$1="",$BE5=0),"",IFERROR(LOOKUP(2,1/((Budgets!$A$2:$A$200=AP$1)*(Budgets!$B$2:$B$200<=$A5)),Budgets!$C$2:$C$200),0)) | AQ5: =IF(OR(AQ$1="",$BE5=0),"",IFERROR(LOOKUP(2,1/((Budgets!$A$2:$A$200=AQ$1)*(Budgets!$B$2:$B$200<=$A5)),Budgets!$C$2:$C$200),0)) | ... BC5: =IF(OR(BC$1="",$BE5=0),"",IFERROR(LOOKUP(2,1/((Budgets!$A$2:$A$200=BC$1)*(Budgets!$B$2:$B$200<=$A5)),Budgets!$C$2:$C$200),0)) | BE5: =COUNTIFS(Entries!$A$2:$A$5000,$A5)
A6: 39569 | B6: =IF($BE6=0,NA(),SUMIFS(Entries!$D$2:$D$5000,Entries!$C$2:$C$5000,"Income",Entries!$A$2:$A$5000,$A6)) | C6: =IF($BE6=0,"",SUMIFS(Entries!$D$2:$D$5000,Entries!$C$2:$C$5000,"Actual",Entries!$A$2:$A$5000,$A6)) | D6: =IF($BE6=0,"",SUMIFS(Entries!$D$2:$D$5000,Entries!$C$2:$C$5000,"One-off",Entries!$A$2:$A$5000,$A6)) | E6: =IF($BE6=0,NA(),C6+D6) | F6: =IF($BE6=0,"",SUM(AJ6:BC6)) | G6: =IF($BE6=0,"",B6-E6) | H6: =IF($BE6=0,"",SUM($G$2:G6)) | I6: =IF($BE6=0,"",SUMIFS(Entries!$F$2:$F$5000,Entries!$A$2:$A$5000,$A6)) | J6: =IF($BE6=0,NA(),H6+SUM($I$2:I6)) | K6: ="" | L6: ="" | M6: =NA() | O6: =IF(OR(O$1="",$BE6=0),"",SUMIFS(Entries!$D$2:$D$5000,Entries!$C$2:$C$5000,"Actual",Entries!$A$2:$A$5000,$A6,Entries!$B$2:$B$5000,O$1)) | P6: =IF(OR(P$1="",$BE6=0),"",SUMIFS(Entries!$D$2:$D$5000,Entries!$C$2:$C$5000,"Actual",Entries!$A$2:$A$5000,$A6,Entries!$B$2:$B$5000,P$1)) | Q6: =IF(OR(Q$1="",$BE6=0),"",SUMIFS(Entries!$D$2:$D$5000,Entries!$C$2:$C$5000,"Actual",Entries!$A$2:$A$5000,$A6,Entries!$B$2:$B$5000,Q$1)) | R6: =IF(OR(R$1="",$BE6=0),"",SUMIFS(Entries!$D$2:$D$5000,Entries!$C$2:$C$5000,"Actual",Entries!$A$2:$A$5000,$A6,Entries!$B$2:$B$5000,R$1)) | S6: =IF(OR(S$1="",$BE6=0),"",SUMIFS(Entries!$D$2:$D$5000,Entries!$C$2:$C$5000,"Actual",Entries!$A$2:$A$5000,$A6,Entries!$B$2:$B$5000,S$1)) | T6: =IF(OR(T$1="",$BE6=0),"",SUMIFS(Entries!$D$2:$D$5000,Entries!$C$2:$C$5000,"Actual",Entries!$A$2:$A$5000,$A6,Entries!$B$2:$B$5000,T$1)) | U6: =IF(OR(U$1="",$BE6=0),"",SUMIFS(Entries!$D$2:$D$5000,Entries!$C$2:$C$5000,"Actual",Entries!$A$2:$A$5000,$A6,Entries!$B$2:$B$5000,U$1)) | V6: =IF(OR(V$1="",$BE6=0),"",SUMIFS(Entries!$D$2:$D$5000,Entries!$C$2:$C$5000,"Actual",Entries!$A$2:$A$5000,$A6,Entries!$B$2:$B$5000,V$1)) | ... AH6: =IF(OR(AH$1="",$BE6=0),"",SUMIFS(Entries!$D$2:$D$5000,Entries!$C$2:$C$5000,"Actual",Entries!$A$2:$A$5000,$A6,Entries!$B$2:$B$5000,AH$1)) | AJ6: =IF(OR(AJ$1="",$BE6=0),"",IFERROR(LOOKUP(2,1/((Budgets!$A$2:$A$200=AJ$1)*(Budgets!$B$2:$B$200<=$A6)),Budgets!$C$2:$C$200),0)) | AK6: =IF(OR(AK$1="",$BE6=0),"",IFERROR(LOOKUP(2,1/((Budgets!$A$2:$A$200=AK$1)*(Budgets!$B$2:$B$200<=$A6)),Budgets!$C$2:$C$200),0)) | AL6: =IF(OR(AL$1="",$BE6=0),"",IFERROR(LOOKUP(2,1/((Budgets!$A$2:$A$200=AL$1)*(Budgets!$B$2:$B$200<=$A6)),Budgets!$C$2:$C$200),0)) | AM6: =IF(OR(AM$1="",$BE6=0),"",IFERROR(LOOKUP(2,1/((Budgets!$A$2:$A$200=AM$1)*(Budgets!$B$2:$B$200<=$A6)),Budgets!$C$2:$C$200),0)) | AN6: =IF(OR(AN$1="",$BE6=0),"",IFERROR(LOOKUP(2,1/((Budgets!$A$2:$A$200=AN$1)*(Budgets!$B$2:$B$200<=$A6)),Budgets!$C$2:$C$200),0)) | AO6: =IF(OR(AO$1="",$BE6=0),"",IFERROR(LOOKUP(2,1/((Budgets!$A$2:$A$200=AO$1)*(Budgets!$B$2:$B$200<=$A6)),Budgets!$C$2:$C$200),0)) | AP6: =IF(OR(AP$1="",$BE6=0),"",IFERROR(LOOKUP(2,1/((Budgets!$A$2:$A$200=AP$1)*(Budgets!$B$2:$B$200<=$A6)),Budgets!$C$2:$C$200),0)) | AQ6: =IF(OR(AQ$1="",$BE6=0),"",IFERROR(LOOKUP(2,1/((Budgets!$A$2:$A$200=AQ$1)*(Budgets!$B$2:$B$200<=$A6)),Budgets!$C$2:$C$200),0)) | ... BC6: =IF(OR(BC$1="",$BE6=0),"",IFERROR(LOOKUP(2,1/((Budgets!$A$2:$A$200=BC$1)*(Budgets!$B$2:$B$200<=$A6)),Budgets!$C$2:$C$200),0)) | BE6: =COUNTIFS(Entries!$A$2:$A$5000,$A6)
A7: 39600 | B7: =IF($BE7=0,NA(),SUMIFS(Entries!$D$2:$D$5000,Entries!$C$2:$C$5000,"Income",Entries!$A$2:$A$5000,$A7)) | C7: =IF($BE7=0,"",SUMIFS(Entries!$D$2:$D$5000,Entries!$C$2:$C$5000,"Actual",Entries!$A$2:$A$5000,$A7)) | D7: =IF($BE7=0,"",SUMIFS(Entries!$D$2:$D$5000,Entries!$C$2:$C$5000,"One-off",Entries!$A$2:$A$5000,$A7)) | E7: =IF($BE7=0,NA(),C7+D7) | F7: =IF($BE7=0,"",SUM(AJ7:BC7)) | G7: =IF($BE7=0,"",B7-E7) | H7: =IF($BE7=0,"",SUM($G$2:G7)) | I7: =IF($BE7=0,"",SUMIFS(Entries!$F$2:$F$5000,Entries!$A$2:$A$5000,$A7)) | J7: =IF($BE7=0,NA(),H7+SUM($I$2:I7)) | K7: ="" | L7: ="" | M7: =NA() | O7: =IF(OR(O$1="",$BE7=0),"",SUMIFS(Entries!$D$2:$D$5000,Entries!$C$2:$C$5000,"Actual",Entries!$A$2:$A$5000,$A7,Entries!$B$2:$B$5000,O$1)) | P7: =IF(OR(P$1="",$BE7=0),"",SUMIFS(Entries!$D$2:$D$5000,Entries!$C$2:$C$5000,"Actual",Entries!$A$2:$A$5000,$A7,Entries!$B$2:$B$5000,P$1)) | Q7: =IF(OR(Q$1="",$BE7=0),"",SUMIFS(Entries!$D$2:$D$5000,Entries!$C$2:$C$5000,"Actual",Entries!$A$2:$A$5000,$A7,Entries!$B$2:$B$5000,Q$1)) | R7: =IF(OR(R$1="",$BE7=0),"",SUMIFS(Entries!$D$2:$D$5000,Entries!$C$2:$C$5000,"Actual",Entries!$A$2:$A$5000,$A7,Entries!$B$2:$B$5000,R$1)) | S7: =IF(OR(S$1="",$BE7=0),"",SUMIFS(Entries!$D$2:$D$5000,Entries!$C$2:$C$5000,"Actual",Entries!$A$2:$A$5000,$A7,Entries!$B$2:$B$5000,S$1)) | T7: =IF(OR(T$1="",$BE7=0),"",SUMIFS(Entries!$D$2:$D$5000,Entries!$C$2:$C$5000,"Actual",Entries!$A$2:$A$5000,$A7,Entries!$B$2:$B$5000,T$1)) | U7: =IF(OR(U$1="",$BE7=0),"",SUMIFS(Entries!$D$2:$D$5000,Entries!$C$2:$C$5000,"Actual",Entries!$A$2:$A$5000,$A7,Entries!$B$2:$B$5000,U$1)) | V7: =IF(OR(V$1="",$BE7=0),"",SUMIFS(Entries!$D$2:$D$5000,Entries!$C$2:$C$5000,"Actual",Entries!$A$2:$A$5000,$A7,Entries!$B$2:$B$5000,V$1)) | ... AH7: =IF(OR(AH$1="",$BE7=0),"",SUMIFS(Entries!$D$2:$D$5000,Entries!$C$2:$C$5000,"Actual",Entries!$A$2:$A$5000,$A7,Entries!$B$2:$B$5000,AH$1)) | AJ7: =IF(OR(AJ$1="",$BE7=0),"",IFERROR(LOOKUP(2,1/((Budgets!$A$2:$A$200=AJ$1)*(Budgets!$B$2:$B$200<=$A7)),Budgets!$C$2:$C$200),0)) | AK7: =IF(OR(AK$1="",$BE7=0),"",IFERROR(LOOKUP(2,1/((Budgets!$A$2:$A$200=AK$1)*(Budgets!$B$2:$B$200<=$A7)),Budgets!$C$2:$C$200),0)) | AL7: =IF(OR(AL$1="",$BE7=0),"",IFERROR(LOOKUP(2,1/((Budgets!$A$2:$A$200=AL$1)*(Budgets!$B$2:$B$200<=$A7)),Budgets!$C$2:$C$200),0)) | AM7: =IF(OR(AM$1="",$BE7=0),"",IFERROR(LOOKUP(2,1/((Budgets!$A$2:$A$200=AM$1)*(Budgets!$B$2:$B$200<=$A7)),Budgets!$C$2:$C$200),0)) | AN7: =IF(OR(AN$1="",$BE7=0),"",IFERROR(LOOKUP(2,1/((Budgets!$A$2:$A$200=AN$1)*(Budgets!$B$2:$B$200<=$A7)),Budgets!$C$2:$C$200),0)) | AO7: =IF(OR(AO$1="",$BE7=0),"",IFERROR(LOOKUP(2,1/((Budgets!$A$2:$A$200=AO$1)*(Budgets!$B$2:$B$200<=$A7)),Budgets!$C$2:$C$200),0)) | AP7: =IF(OR(AP$1="",$BE7=0),"",IFERROR(LOOKUP(2,1/((Budgets!$A$2:$A$200=AP$1)*(Budgets!$B$2:$B$200<=$A7)),Budgets!$C$2:$C$200),0)) | AQ7: =IF(OR(AQ$1="",$BE7=0),"",IFERROR(LOOKUP(2,1/((Budgets!$A$2:$A$200=AQ$1)*(Budgets!$B$2:$B$200<=$A7)),Budgets!$C$2:$C$200),0)) | ... BC7: =IF(OR(BC$1="",$BE7=0),"",IFERROR(LOOKUP(2,1/((Budgets!$A$2:$A$200=BC$1)*(Budgets!$B$2:$B$200<=$A7)),Budgets!$C$2:$C$200),0)) | BE7: =COUNTIFS(Entries!$A$2:$A$5000,$A7)
A8: 39630 | B8: =IF($BE8=0,NA(),SUMIFS(Entries!$D$2:$D$5000,Entries!$C$2:$C$5000,"Income",Entries!$A$2:$A$5000,$A8)) | C8: =IF($BE8=0,"",SUMIFS(Entries!$D$2:$D$5000,Entries!$C$2:$C$5000,"Actual",Entries!$A$2:$A$5000,$A8)) | D8: =IF($BE8=0,"",SUMIFS(Entries!$D$2:$D$5000,Entries!$C$2:$C$5000,"One-off",Entries!$A$2:$A$5000,$A8)) | E8: =IF($BE8=0,NA(),C8+D8) | F8: =IF($BE8=0,"",SUM(AJ8:BC8)) | G8: =IF($BE8=0,"",B8-E8) | H8: =IF($BE8=0,"",SUM($G$2:G8)) | I8: =IF($BE8=0,"",SUMIFS(Entries!$F$2:$F$5000,Entries!$A$2:$A$5000,$A8)) | J8: =IF($BE8=0,NA(),H8+SUM($I$2:I8)) | K8: ="" | L8: ="" | M8: =NA() | O8: =IF(OR(O$1="",$BE8=0),"",SUMIFS(Entries!$D$2:$D$5000,Entries!$C$2:$C$5000,"Actual",Entries!$A$2:$A$5000,$A8,Entries!$B$2:$B$5000,O$1)) | P8: =IF(OR(P$1="",$BE8=0),"",SUMIFS(Entries!$D$2:$D$5000,Entries!$C$2:$C$5000,"Actual",Entries!$A$2:$A$5000,$A8,Entries!$B$2:$B$5000,P$1)) | Q8: =IF(OR(Q$1="",$BE8=0),"",SUMIFS(Entries!$D$2:$D$5000,Entries!$C$2:$C$5000,"Actual",Entries!$A$2:$A$5000,$A8,Entries!$B$2:$B$5000,Q$1)) | R8: =IF(OR(R$1="",$BE8=0),"",SUMIFS(Entries!$D$2:$D$5000,Entries!$C$2:$C$5000,"Actual",Entries!$A$2:$A$5000,$A8,Entries!$B$2:$B$5000,R$1)) | S8: =IF(OR(S$1="",$BE8=0),"",SUMIFS(Entries!$D$2:$D$5000,Entries!$C$2:$C$5000,"Actual",Entries!$A$2:$A$5000,$A8,Entries!$B$2:$B$5000,S$1)) | T8: =IF(OR(T$1="",$BE8=0),"",SUMIFS(Entries!$D$2:$D$5000,Entries!$C$2:$C$5000,"Actual",Entries!$A$2:$A$5000,$A8,Entries!$B$2:$B$5000,T$1)) | U8: =IF(OR(U$1="",$BE8=0),"",SUMIFS(Entries!$D$2:$D$5000,Entries!$C$2:$C$5000,"Actual",Entries!$A$2:$A$5000,$A8,Entries!$B$2:$B$5000,U$1)) | V8: =IF(OR(V$1="",$BE8=0),"",SUMIFS(Entries!$D$2:$D$5000,Entries!$C$2:$C$5000,"Actual",Entries!$A$2:$A$5000,$A8,Entries!$B$2:$B$5000,V$1)) | ... AH8: =IF(OR(AH$1="",$BE8=0),"",SUMIFS(Entries!$D$2:$D$5000,Entries!$C$2:$C$5000,"Actual",Entries!$A$2:$A$5000,$A8,Entries!$B$2:$B$5000,AH$1)) | AJ8: =IF(OR(AJ$1="",$BE8=0),"",IFERROR(LOOKUP(2,1/((Budgets!$A$2:$A$200=AJ$1)*(Budgets!$B$2:$B$200<=$A8)),Budgets!$C$2:$C$200),0)) | AK8: =IF(OR(AK$1="",$BE8=0),"",IFERROR(LOOKUP(2,1/((Budgets!$A$2:$A$200=AK$1)*(Budgets!$B$2:$B$200<=$A8)),Budgets!$C$2:$C$200),0)) | AL8: =IF(OR(AL$1="",$BE8=0),"",IFERROR(LOOKUP(2,1/((Budgets!$A$2:$A$200=AL$1)*(Budgets!$B$2:$B$200<=$A8)),Budgets!$C$2:$C$200),0)) | AM8: =IF(OR(AM$1="",$BE8=0),"",IFERROR(LOOKUP(2,1/((Budgets!$A$2:$A$200=AM$1)*(Budgets!$B$2:$B$200<=$A8)),Budgets!$C$2:$C$200),0)) | AN8: =IF(OR(AN$1="",$BE8=0),"",IFERROR(LOOKUP(2,1/((Budgets!$A$2:$A$200=AN$1)*(Budgets!$B$2:$B$200<=$A8)),Budgets!$C$2:$C$200),0)) | AO8: =IF(OR(AO$1="",$BE8=0),"",IFERROR(LOOKUP(2,1/((Budgets!$A$2:$A$200=AO$1)*(Budgets!$B$2:$B$200<=$A8)),Budgets!$C$2:$C$200),0)) | AP8: =IF(OR(AP$1="",$BE8=0),"",IFERROR(LOOKUP(2,1/((Budgets!$A$2:$A$200=AP$1)*(Budgets!$B$2:$B$200<=$A8)),Budgets!$C$2:$C$200),0)) | AQ8: =IF(OR(AQ$1="",$BE8=0),"",IFERROR(LOOKUP(2,1/((Budgets!$A$2:$A$200=AQ$1)*(Budgets!$B$2:$B$200<=$A8)),Budgets!$C$2:$C$200),0)) | ... BC8: =IF(OR(BC$1="",$BE8=0),"",IFERROR(LOOKUP(2,1/((Budgets!$A$2:$A$200=BC$1)*(Budgets!$B$2:$B$200<=$A8)),Budgets!$C$2:$C$200),0)) | BE8: =COUNTIFS(Entries!$A$2:$A$5000,$A8)
A9: 39661 | B9: =IF($BE9=0,NA(),SUMIFS(Entries!$D$2:$D$5000,Entries!$C$2:$C$5000,"Income",Entries!$A$2:$A$5000,$A9)) | C9: =IF($BE9=0,"",SUMIFS(Entries!$D$2:$D$5000,Entries!$C$2:$C$5000,"Actual",Entries!$A$2:$A$5000,$A9)) | D9: =IF($BE9=0,"",SUMIFS(Entries!$D$2:$D$5000,Entries!$C$2:$C$5000,"One-off",Entries!$A$2:$A$5000,$A9)) | E9: =IF($BE9=0,NA(),C9+D9) | F9: =IF($BE9=0,"",SUM(AJ9:BC9)) | G9: =IF($BE9=0,"",B9-E9) | H9: =IF($BE9=0,"",SUM($G$2:G9)) | I9: =IF($BE9=0,"",SUMIFS(Entries!$F$2:$F$5000,Entries!$A$2:$A$5000,$A9)) | J9: =IF($BE9=0,NA(),H9+SUM($I$2:I9)) | K9: ="" | L9: ="" | M9: =NA() | O9: =IF(OR(O$1="",$BE9=0),"",SUMIFS(Entries!$D$2:$D$5000,Entries!$C$2:$C$5000,"Actual",Entries!$A$2:$A$5000,$A9,Entries!$B$2:$B$5000,O$1)) | P9: =IF(OR(P$1="",$BE9=0),"",SUMIFS(Entries!$D$2:$D$5000,Entries!$C$2:$C$5000,"Actual",Entries!$A$2:$A$5000,$A9,Entries!$B$2:$B$5000,P$1)) | Q9: =IF(OR(Q$1="",$BE9=0),"",SUMIFS(Entries!$D$2:$D$5000,Entries!$C$2:$C$5000,"Actual",Entries!$A$2:$A$5000,$A9,Entries!$B$2:$B$5000,Q$1)) | R9: =IF(OR(R$1="",$BE9=0),"",SUMIFS(Entries!$D$2:$D$5000,Entries!$C$2:$C$5000,"Actual",Entries!$A$2:$A$5000,$A9,Entries!$B$2:$B$5000,R$1)) | S9: =IF(OR(S$1="",$BE9=0),"",SUMIFS(Entries!$D$2:$D$5000,Entries!$C$2:$C$5000,"Actual",Entries!$A$2:$A$5000,$A9,Entries!$B$2:$B$5000,S$1)) | T9: =IF(OR(T$1="",$BE9=0),"",SUMIFS(Entries!$D$2:$D$5000,Entries!$C$2:$C$5000,"Actual",Entries!$A$2:$A$5000,$A9,Entries!$B$2:$B$5000,T$1)) | U9: =IF(OR(U$1="",$BE9=0),"",SUMIFS(Entries!$D$2:$D$5000,Entries!$C$2:$C$5000,"Actual",Entries!$A$2:$A$5000,$A9,Entries!$B$2:$B$5000,U$1)) | V9: =IF(OR(V$1="",$BE9=0),"",SUMIFS(Entries!$D$2:$D$5000,Entries!$C$2:$C$5000,"Actual",Entries!$A$2:$A$5000,$A9,Entries!$B$2:$B$5000,V$1)) | ... AH9: =IF(OR(AH$1="",$BE9=0),"",SUMIFS(Entries!$D$2:$D$5000,Entries!$C$2:$C$5000,"Actual",Entries!$A$2:$A$5000,$A9,Entries!$B$2:$B$5000,AH$1)) | AJ9: =IF(OR(AJ$1="",$BE9=0),"",IFERROR(LOOKUP(2,1/((Budgets!$A$2:$A$200=AJ$1)*(Budgets!$B$2:$B$200<=$A9)),Budgets!$C$2:$C$200),0)) | AK9: =IF(OR(AK$1="",$BE9=0),"",IFERROR(LOOKUP(2,1/((Budgets!$A$2:$A$200=AK$1)*(Budgets!$B$2:$B$200<=$A9)),Budgets!$C$2:$C$200),0)) | AL9: =IF(OR(AL$1="",$BE9=0),"",IFERROR(LOOKUP(2,1/((Budgets!$A$2:$A$200=AL$1)*(Budgets!$B$2:$B$200<=$A9)),Budgets!$C$2:$C$200),0)) | AM9: =IF(OR(AM$1="",$BE9=0),"",IFERROR(LOOKUP(2,1/((Budgets!$A$2:$A$200=AM$1)*(Budgets!$B$2:$B$200<=$A9)),Budgets!$C$2:$C$200),0)) | AN9: =IF(OR(AN$1="",$BE9=0),"",IFERROR(LOOKUP(2,1/((Budgets!$A$2:$A$200=AN$1)*(Budgets!$B$2:$B$200<=$A9)),Budgets!$C$2:$C$200),0)) | AO9: =IF(OR(AO$1="",$BE9=0),"",IFERROR(LOOKUP(2,1/((Budgets!$A$2:$A$200=AO$1)*(Budgets!$B$2:$B$200<=$A9)),Budgets!$C$2:$C$200),0)) | AP9: =IF(OR(AP$1="",$BE9=0),"",IFERROR(LOOKUP(2,1/((Budgets!$A$2:$A$200=AP$1)*(Budgets!$B$2:$B$200<=$A9)),Budgets!$C$2:$C$200),0)) | AQ9: =IF(OR(AQ$1="",$BE9=0),"",IFERROR(LOOKUP(2,1/((Budgets!$A$2:$A$200=AQ$1)*(Budgets!$B$2:$B$200<=$A9)),Budgets!$C$2:$C$200),0)) | ... BC9: =IF(OR(BC$1="",$BE9=0),"",IFERROR(LOOKUP(2,1/((Budgets!$A$2:$A$200=BC$1)*(Budgets!$B$2:$B$200<=$A9)),Budgets!$C$2:$C$200),0)) | BE9: =COUNTIFS(Entries!$A$2:$A$5000,$A9)
A10: 39692 | B10: =IF($BE10=0,NA(),SUMIFS(Entries!$D$2:$D$5000,Entries!$C$2:$C$5000,"Income",Entries!$A$2:$A$5000,$A10)) | C10: =IF($BE10=0,"",SUMIFS(Entries!$D$2:$D$5000,Entries!$C$2:$C$5000,"Actual",Entries!$A$2:$A$5000,$A10)) | D10: =IF($BE10=0,"",SUMIFS(Entries!$D$2:$D$5000,Entries!$C$2:$C$5000,"One-off",Entries!$A$2:$A$5000,$A10)) | E10: =IF($BE10=0,NA(),C10+D10) | F10: =IF($BE10=0,"",SUM(AJ10:BC10)) | G10: =IF($BE10=0,"",B10-E10) | H10: =IF($BE10=0,"",SUM($G$2:G10)) | I10: =IF($BE10=0,"",SUMIFS(Entries!$F$2:$F$5000,Entries!$A$2:$A$5000,$A10)) | J10: =IF($BE10=0,NA(),H10+SUM($I$2:I10)) | K10: ="" | L10: ="" | M10: =NA() | O10: =IF(OR(O$1="",$BE10=0),"",SUMIFS(Entries!$D$2:$D$5000,Entries!$C$2:$C$5000,"Actual",Entries!$A$2:$A$5000,$A10,Entries!$B$2:$B$5000,O$1)) | P10: =IF(OR(P$1="",$BE10=0),"",SUMIFS(Entries!$D$2:$D$5000,Entries!$C$2:$C$5000,"Actual",Entries!$A$2:$A$5000,$A10,Entries!$B$2:$B$5000,P$1)) | Q10: =IF(OR(Q$1="",$BE10=0),"",SUMIFS(Entries!$D$2:$D$5000,Entries!$C$2:$C$5000,"Actual",Entries!$A$2:$A$5000,$A10,Entries!$B$2:$B$5000,Q$1)) | R10: =IF(OR(R$1="",$BE10=0),"",SUMIFS(Entries!$D$2:$D$5000,Entries!$C$2:$C$5000,"Actual",Entries!$A$2:$A$5000,$A10,Entries!$B$2:$B$5000,R$1)) | S10: =IF(OR(S$1="",$BE10=0),"",SUMIFS(Entries!$D$2:$D$5000,Entries!$C$2:$C$5000,"Actual",Entries!$A$2:$A$5000,$A10,Entries!$B$2:$B$5000,S$1)) | T10: =IF(OR(T$1="",$BE10=0),"",SUMIFS(Entries!$D$2:$D$5000,Entries!$C$2:$C$5000,"Actual",Entries!$A$2:$A$5000,$A10,Entries!$B$2:$B$5000,T$1)) | U10: =IF(OR(U$1="",$BE10=0),"",SUMIFS(Entries!$D$2:$D$5000,Entries!$C$2:$C$5000,"Actual",Entries!$A$2:$A$5000,$A10,Entries!$B$2:$B$5000,U$1)) | V10: =IF(OR(V$1="",$BE10=0),"",SUMIFS(Entries!$D$2:$D$5000,Entries!$C$2:$C$5000,"Actual",Entries!$A$2:$A$5000,$A10,Entries!$B$2:$B$5000,V$1)) | ... AH10: =IF(OR(AH$1="",$BE10=0),"",SUMIFS(Entries!$D$2:$D$5000,Entries!$C$2:$C$5000,"Actual",Entries!$A$2:$A$5000,$A10,Entries!$B$2:$B$5000,AH$1)) | AJ10: =IF(OR(AJ$1="",$BE10=0),"",IFERROR(LOOKUP(2,1/((Budgets!$A$2:$A$200=AJ$1)*(Budgets!$B$2:$B$200<=$A10)),Budgets!$C$2:$C$200),0)) | AK10: =IF(OR(AK$1="",$BE10=0),"",IFERROR(LOOKUP(2,1/((Budgets!$A$2:$A$200=AK$1)*(Budgets!$B$2:$B$200<=$A10)),Budgets!$C$2:$C$200),0)) | AL10: =IF(OR(AL$1="",$BE10=0),"",IFERROR(LOOKUP(2,1/((Budgets!$A$2:$A$200=AL$1)*(Budgets!$B$2:$B$200<=$A10)),Budgets!$C$2:$C$200),0)) | AM10: =IF(OR(AM$1="",$BE10=0),"",IFERROR(LOOKUP(2,1/((Budgets!$A$2:$A$200=AM$1)*(Budgets!$B$2:$B$200<=$A10)),Budgets!$C$2:$C$200),0)) | AN10: =IF(OR(AN$1="",$BE10=0),"",IFERROR(LOOKUP(2,1/((Budgets!$A$2:$A$200=AN$1)*(Budgets!$B$2:$B$200<=$A10)),Budgets!$C$2:$C$200),0)) | AO10: =IF(OR(AO$1="",$BE10=0),"",IFERROR(LOOKUP(2,1/((Budgets!$A$2:$A$200=AO$1)*(Budgets!$B$2:$B$200<=$A10)),Budgets!$C$2:$C$200),0)) | AP10: =IF(OR(AP$1="",$BE10=0),"",IFERROR(LOOKUP(2,1/((Budgets!$A$2:$A$200=AP$1)*(Budgets!$B$2:$B$200<=$A10)),Budgets!$C$2:$C$200),0)) | AQ10: =IF(OR(AQ$1="",$BE10=0),"",IFERROR(LOOKUP(2,1/((Budgets!$A$2:$A$200=AQ$1)*(Budgets!$B$2:$B$200<=$A10)),Budgets!$C$2:$C$200),0)) | ... BC10: =IF(OR(BC$1="",$BE10=0),"",IFERROR(LOOKUP(2,1/((Budgets!$A$2:$A$200=BC$1)*(Budgets!$B$2:$B$200<=$A10)),Budgets!$C$2:$C$200),0)) | BE10: =COUNTIFS(Entries!$A$2:$A$5000,$A10)
A11: 39722 | B11: =IF($BE11=0,NA(),SUMIFS(Entries!$D$2:$D$5000,Entries!$C$2:$C$5000,"Income",Entries!$A$2:$A$5000,$A11)) | C11: =IF($BE11=0,"",SUMIFS(Entries!$D$2:$D$5000,Entries!$C$2:$C$5000,"Actual",Entries!$A$2:$A$5000,$A11)) | D11: =IF($BE11=0,"",SUMIFS(Entries!$D$2:$D$5000,Entries!$C$2:$C$5000,"One-off",Entries!$A$2:$A$5000,$A11)) | E11: =IF($BE11=0,NA(),C11+D11) | F11: =IF($BE11=0,"",SUM(AJ11:BC11)) | G11: =IF($BE11=0,"",B11-E11) | H11: =IF($BE11=0,"",SUM($G$2:G11)) | I11: =IF($BE11=0,"",SUMIFS(Entries!$F$2:$F$5000,Entries!$A$2:$A$5000,$A11)) | J11: =IF($BE11=0,NA(),H11+SUM($I$2:I11)) | K11: ="" | L11: ="" | M11: =NA() | O11: =IF(OR(O$1="",$BE11=0),"",SUMIFS(Entries!$D$2:$D$5000,Entries!$C$2:$C$5000,"Actual",Entries!$A$2:$A$5000,$A11,Entries!$B$2:$B$5000,O$1)) | P11: =IF(OR(P$1="",$BE11=0),"",SUMIFS(Entries!$D$2:$D$5000,Entries!$C$2:$C$5000,"Actual",Entries!$A$2:$A$5000,$A11,Entries!$B$2:$B$5000,P$1)) | Q11: =IF(OR(Q$1="",$BE11=0),"",SUMIFS(Entries!$D$2:$D$5000,Entries!$C$2:$C$5000,"Actual",Entries!$A$2:$A$5000,$A11,Entries!$B$2:$B$5000,Q$1)) | R11: =IF(OR(R$1="",$BE11=0),"",SUMIFS(Entries!$D$2:$D$5000,Entries!$C$2:$C$5000,"Actual",Entries!$A$2:$A$5000,$A11,Entries!$B$2:$B$5000,R$1)) | S11: =IF(OR(S$1="",$BE11=0),"",SUMIFS(Entries!$D$2:$D$5000,Entries!$C$2:$C$5000,"Actual",Entries!$A$2:$A$5000,$A11,Entries!$B$2:$B$5000,S$1)) | T11: =IF(OR(T$1="",$BE11=0),"",SUMIFS(Entries!$D$2:$D$5000,Entries!$C$2:$C$5000,"Actual",Entries!$A$2:$A$5000,$A11,Entries!$B$2:$B$5000,T$1)) | U11: =IF(OR(U$1="",$BE11=0),"",SUMIFS(Entries!$D$2:$D$5000,Entries!$C$2:$C$5000,"Actual",Entries!$A$2:$A$5000,$A11,Entries!$B$2:$B$5000,U$1)) | V11: =IF(OR(V$1="",$BE11=0),"",SUMIFS(Entries!$D$2:$D$5000,Entries!$C$2:$C$5000,"Actual",Entries!$A$2:$A$5000,$A11,Entries!$B$2:$B$5000,V$1)) | ... AH11: =IF(OR(AH$1="",$BE11=0),"",SUMIFS(Entries!$D$2:$D$5000,Entries!$C$2:$C$5000,"Actual",Entries!$A$2:$A$5000,$A11,Entries!$B$2:$B$5000,AH$1)) | AJ11: =IF(OR(AJ$1="",$BE11=0),"",IFERROR(LOOKUP(2,1/((Budgets!$A$2:$A$200=AJ$1)*(Budgets!$B$2:$B$200<=$A11)),Budgets!$C$2:$C$200),0)) | AK11: =IF(OR(AK$1="",$BE11=0),"",IFERROR(LOOKUP(2,1/((Budgets!$A$2:$A$200=AK$1)*(Budgets!$B$2:$B$200<=$A11)),Budgets!$C$2:$C$200),0)) | AL11: =IF(OR(AL$1="",$BE11=0),"",IFERROR(LOOKUP(2,1/((Budgets!$A$2:$A$200=AL$1)*(Budgets!$B$2:$B$200<=$A11)),Budgets!$C$2:$C$200),0)) | AM11: =IF(OR(AM$1="",$BE11=0),"",IFERROR(LOOKUP(2,1/((Budgets!$A$2:$A$200=AM$1)*(Budgets!$B$2:$B$200<=$A11)),Budgets!$C$2:$C$200),0)) | AN11: =IF(OR(AN$1="",$BE11=0),"",IFERROR(LOOKUP(2,1/((Budgets!$A$2:$A$200=AN$1)*(Budgets!$B$2:$B$200<=$A11)),Budgets!$C$2:$C$200),0)) | AO11: =IF(OR(AO$1="",$BE11=0),"",IFERROR(LOOKUP(2,1/((Budgets!$A$2:$A$200=AO$1)*(Budgets!$B$2:$B$200<=$A11)),Budgets!$C$2:$C$200),0)) | AP11: =IF(OR(AP$1="",$BE11=0),"",IFERROR(LOOKUP(2,1/((Budgets!$A$2:$A$200=AP$1)*(Budgets!$B$2:$B$200<=$A11)),Budgets!$C$2:$C$200),0)) | AQ11: =IF(OR(AQ$1="",$BE11=0),"",IFERROR(LOOKUP(2,1/((Budgets!$A$2:$A$200=AQ$1)*(Budgets!$B$2:$B$200<=$A11)),Budgets!$C$2:$C$200),0)) | ... BC11: =IF(OR(BC$1="",$BE11=0),"",IFERROR(LOOKUP(2,1/((Budgets!$A$2:$A$200=BC$1)*(Budgets!$B$2:$B$200<=$A11)),Budgets!$C$2:$C$200),0)) | BE11: =COUNTIFS(Entries!$A$2:$A$5000,$A11)
A12: 39753 | B12: =IF($BE12=0,NA(),SUMIFS(Entries!$D$2:$D$5000,Entries!$C$2:$C$5000,"Income",Entries!$A$2:$A$5000,$A12)) | C12: =IF($BE12=0,"",SUMIFS(Entries!$D$2:$D$5000,Entries!$C$2:$C$5000,"Actual",Entries!$A$2:$A$5000,$A12)) | D12: =IF($BE12=0,"",SUMIFS(Entries!$D$2:$D$5000,Entries!$C$2:$C$5000,"One-off",Entries!$A$2:$A$5000,$A12)) | E12: =IF($BE12=0,NA(),C12+D12) | F12: =IF($BE12=0,"",SUM(AJ12:BC12)) | G12: =IF($BE12=0,"",B12-E12) | H12: =IF($BE12=0,"",SUM($G$2:G12)) | I12: =IF($BE12=0,"",SUMIFS(Entries!$F$2:$F$5000,Entries!$A$2:$A$5000,$A12)) | J12: =IF($BE12=0,NA(),H12+SUM($I$2:I12)) | K12: ="" | L12: ="" | M12: =NA() | O12: =IF(OR(O$1="",$BE12=0),"",SUMIFS(Entries!$D$2:$D$5000,Entries!$C$2:$C$5000,"Actual",Entries!$A$2:$A$5000,$A12,Entries!$B$2:$B$5000,O$1)) | P12: =IF(OR(P$1="",$BE12=0),"",SUMIFS(Entries!$D$2:$D$5000,Entries!$C$2:$C$5000,"Actual",Entries!$A$2:$A$5000,$A12,Entries!$B$2:$B$5000,P$1)) | Q12: =IF(OR(Q$1="",$BE12=0),"",SUMIFS(Entries!$D$2:$D$5000,Entries!$C$2:$C$5000,"Actual",Entries!$A$2:$A$5000,$A12,Entries!$B$2:$B$5000,Q$1)) | R12: =IF(OR(R$1="",$BE12=0),"",SUMIFS(Entries!$D$2:$D$5000,Entries!$C$2:$C$5000,"Actual",Entries!$A$2:$A$5000,$A12,Entries!$B$2:$B$5000,R$1)) | S12: =IF(OR(S$1="",$BE12=0),"",SUMIFS(Entries!$D$2:$D$5000,Entries!$C$2:$C$5000,"Actual",Entries!$A$2:$A$5000,$A12,Entries!$B$2:$B$5000,S$1)) | T12: =IF(OR(T$1="",$BE12=0),"",SUMIFS(Entries!$D$2:$D$5000,Entries!$C$2:$C$5000,"Actual",Entries!$A$2:$A$5000,$A12,Entries!$B$2:$B$5000,T$1)) | U12: =IF(OR(U$1="",$BE12=0),"",SUMIFS(Entries!$D$2:$D$5000,Entries!$C$2:$C$5000,"Actual",Entries!$A$2:$A$5000,$A12,Entries!$B$2:$B$5000,U$1)) | V12: =IF(OR(V$1="",$BE12=0),"",SUMIFS(Entries!$D$2:$D$5000,Entries!$C$2:$C$5000,"Actual",Entries!$A$2:$A$5000,$A12,Entries!$B$2:$B$5000,V$1)) | ... AH12: =IF(OR(AH$1="",$BE12=0),"",SUMIFS(Entries!$D$2:$D$5000,Entries!$C$2:$C$5000,"Actual",Entries!$A$2:$A$5000,$A12,Entries!$B$2:$B$5000,AH$1)) | AJ12: =IF(OR(AJ$1="",$BE12=0),"",IFERROR(LOOKUP(2,1/((Budgets!$A$2:$A$200=AJ$1)*(Budgets!$B$2:$B$200<=$A12)),Budgets!$C$2:$C$200),0)) | AK12: =IF(OR(AK$1="",$BE12=0),"",IFERROR(LOOKUP(2,1/((Budgets!$A$2:$A$200=AK$1)*(Budgets!$B$2:$B$200<=$A12)),Budgets!$C$2:$C$200),0)) | AL12: =IF(OR(AL$1="",$BE12=0),"",IFERROR(LOOKUP(2,1/((Budgets!$A$2:$A$200=AL$1)*(Budgets!$B$2:$B$200<=$A12)),Budgets!$C$2:$C$200),0)) | AM12: =IF(OR(AM$1="",$BE12=0),"",IFERROR(LOOKUP(2,1/((Budgets!$A$2:$A$200=AM$1)*(Budgets!$B$2:$B$200<=$A12)),Budgets!$C$2:$C$200),0)) | AN12: =IF(OR(AN$1="",$BE12=0),"",IFERROR(LOOKUP(2,1/((Budgets!$A$2:$A$200=AN$1)*(Budgets!$B$2:$B$200<=$A12)),Budgets!$C$2:$C$200),0)) | AO12: =IF(OR(AO$1="",$BE12=0),"",IFERROR(LOOKUP(2,1/((Budgets!$A$2:$A$200=AO$1)*(Budgets!$B$2:$B$200<=$A12)),Budgets!$C$2:$C$200),0)) | AP12: =IF(OR(AP$1="",$BE12=0),"",IFERROR(LOOKUP(2,1/((Budgets!$A$2:$A$200=AP$1)*(Budgets!$B$2:$B$200<=$A12)),Budgets!$C$2:$C$200),0)) | AQ12: =IF(OR(AQ$1="",$BE12=0),"",IFERROR(LOOKUP(2,1/((Budgets!$A$2:$A$200=AQ$1)*(Budgets!$B$2:$B$200<=$A12)),Budgets!$C$2:$C$200),0)) | ... BC12: =IF(OR(BC$1="",$BE12=0),"",IFERROR(LOOKUP(2,1/((Budgets!$A$2:$A$200=BC$1)*(Budgets!$B$2:$B$200<=$A12)),Budgets!$C$2:$C$200),0)) | BE12: =COUNTIFS(Entries!$A$2:$A$5000,$A12)
A13: 39783 | B13: =IF($BE13=0,NA(),SUMIFS(Entries!$D$2:$D$5000,Entries!$C$2:$C$5000,"Income",Entries!$A$2:$A$5000,$A13)) | C13: =IF($BE13=0,"",SUMIFS(Entries!$D$2:$D$5000,Entries!$C$2:$C$5000,"Actual",Entries!$A$2:$A$5000,$A13)) | D13: =IF($BE13=0,"",SUMIFS(Entries!$D$2:$D$5000,Entries!$C$2:$C$5000,"One-off",Entries!$A$2:$A$5000,$A13)) | E13: =IF($BE13=0,NA(),C13+D13) | F13: =IF($BE13=0,"",SUM(AJ13:BC13)) | G13: =IF($BE13=0,"",B13-E13) | H13: =IF($BE13=0,"",SUM($G$2:G13)) | I13: =IF($BE13=0,"",SUMIFS(Entries!$F$2:$F$5000,Entries!$A$2:$A$5000,$A13)) | J13: =IF($BE13=0,NA(),H13+SUM($I$2:I13)) | K13: =IF($BE13=0,"",SUMIFS(Entries!$D$2:$D$5000,Entries!$C$2:$C$5000,"Income",Entries!$A$2:$A$5000,">="&EDATE($A13,-11),Entries!$A$2:$A$5000,"<="&$A13)/12) | L13: =IF($BE13=0,"",(SUMIFS(Entries!$D$2:$D$5000,Entries!$C$2:$C$5000,"Actual",Entries!$A$2:$A$5000,">="&EDATE($A13,-11),Entries!$A$2:$A$5000,"<="&$A13)+SUMIFS(Entries!$D$2:$D$5000,Entries!$C$2:$C$5000,"One-off",Entries!$A$2:$A$5000,">="&EDATE($A13,-11),Entries!$A$2:$A$5000,"<="&$A13))/12) | M13: =IF($BE13=0,NA(),IFERROR((K13-L13)/K13,0)) | O13: =IF(OR(O$1="",$BE13=0),"",SUMIFS(Entries!$D$2:$D$5000,Entries!$C$2:$C$5000,"Actual",Entries!$A$2:$A$5000,$A13,Entries!$B$2:$B$5000,O$1)) | P13: =IF(OR(P$1="",$BE13=0),"",SUMIFS(Entries!$D$2:$D$5000,Entries!$C$2:$C$5000,"Actual",Entries!$A$2:$A$5000,$A13,Entries!$B$2:$B$5000,P$1)) | Q13: =IF(OR(Q$1="",$BE13=0),"",SUMIFS(Entries!$D$2:$D$5000,Entries!$C$2:$C$5000,"Actual",Entries!$A$2:$A$5000,$A13,Entries!$B$2:$B$5000,Q$1)) | R13: =IF(OR(R$1="",$BE13=0),"",SUMIFS(Entries!$D$2:$D$5000,Entries!$C$2:$C$5000,"Actual",Entries!$A$2:$A$5000,$A13,Entries!$B$2:$B$5000,R$1)) | S13: =IF(OR(S$1="",$BE13=0),"",SUMIFS(Entries!$D$2:$D$5000,Entries!$C$2:$C$5000,"Actual",Entries!$A$2:$A$5000,$A13,Entries!$B$2:$B$5000,S$1)) | T13: =IF(OR(T$1="",$BE13=0),"",SUMIFS(Entries!$D$2:$D$5000,Entries!$C$2:$C$5000,"Actual",Entries!$A$2:$A$5000,$A13,Entries!$B$2:$B$5000,T$1)) | U13: =IF(OR(U$1="",$BE13=0),"",SUMIFS(Entries!$D$2:$D$5000,Entries!$C$2:$C$5000,"Actual",Entries!$A$2:$A$5000,$A13,Entries!$B$2:$B$5000,U$1)) | V13: =IF(OR(V$1="",$BE13=0),"",SUMIFS(Entries!$D$2:$D$5000,Entries!$C$2:$C$5000,"Actual",Entries!$A$2:$A$5000,$A13,Entries!$B$2:$B$5000,V$1)) | ... AH13: =IF(OR(AH$1="",$BE13=0),"",SUMIFS(Entries!$D$2:$D$5000,Entries!$C$2:$C$5000,"Actual",Entries!$A$2:$A$5000,$A13,Entries!$B$2:$B$5000,AH$1)) | AJ13: =IF(OR(AJ$1="",$BE13=0),"",IFERROR(LOOKUP(2,1/((Budgets!$A$2:$A$200=AJ$1)*(Budgets!$B$2:$B$200<=$A13)),Budgets!$C$2:$C$200),0)) | AK13: =IF(OR(AK$1="",$BE13=0),"",IFERROR(LOOKUP(2,1/((Budgets!$A$2:$A$200=AK$1)*(Budgets!$B$2:$B$200<=$A13)),Budgets!$C$2:$C$200),0)) | AL13: =IF(OR(AL$1="",$BE13=0),"",IFERROR(LOOKUP(2,1/((Budgets!$A$2:$A$200=AL$1)*(Budgets!$B$2:$B$200<=$A13)),Budgets!$C$2:$C$200),0)) | AM13: =IF(OR(AM$1="",$BE13=0),"",IFERROR(LOOKUP(2,1/((Budgets!$A$2:$A$200=AM$1)*(Budgets!$B$2:$B$200<=$A13)),Budgets!$C$2:$C$200),0)) | AN13: =IF(OR(AN$1="",$BE13=0),"",IFERROR(LOOKUP(2,1/((Budgets!$A$2:$A$200=AN$1)*(Budgets!$B$2:$B$200<=$A13)),Budgets!$C$2:$C$200),0)) | AO13: =IF(OR(AO$1="",$BE13=0),"",IFERROR(LOOKUP(2,1/((Budgets!$A$2:$A$200=AO$1)*(Budgets!$B$2:$B$200<=$A13)),Budgets!$C$2:$C$200),0)) | AP13: =IF(OR(AP$1="",$BE13=0),"",IFERROR(LOOKUP(2,1/((Budgets!$A$2:$A$200=AP$1)*(Budgets!$B$2:$B$200<=$A13)),Budgets!$C$2:$C$200),0)) | AQ13: =IF(OR(AQ$1="",$BE13=0),"",IFERROR(LOOKUP(2,1/((Budgets!$A$2:$A$200=AQ$1)*(Budgets!$B$2:$B$200<=$A13)),Budgets!$C$2:$C$200),0)) | ... BC13: =IF(OR(BC$1="",$BE13=0),"",IFERROR(LOOKUP(2,1/((Budgets!$A$2:$A$200=BC$1)*(Budgets!$B$2:$B$200<=$A13)),Budgets!$C$2:$C$200),0)) | BE13: =COUNTIFS(Entries!$A$2:$A$5000,$A13)
A14: 39814 | B14: =IF($BE14=0,NA(),SUMIFS(Entries!$D$2:$D$5000,Entries!$C$2:$C$5000,"Income",Entries!$A$2:$A$5000,$A14)) | C14: =IF($BE14=0,"",SUMIFS(Entries!$D$2:$D$5000,Entries!$C$2:$C$5000,"Actual",Entries!$A$2:$A$5000,$A14)) | D14: =IF($BE14=0,"",SUMIFS(Entries!$D$2:$D$5000,Entries!$C$2:$C$5000,"One-off",Entries!$A$2:$A$5000,$A14)) | E14: =IF($BE14=0,NA(),C14+D14) | F14: =IF($BE14=0,"",SUM(AJ14:BC14)) | G14: =IF($BE14=0,"",B14-E14) | H14: =IF($BE14=0,"",SUM($G$2:G14)) | I14: =IF($BE14=0,"",SUMIFS(Entries!$F$2:$F$5000,Entries!$A$2:$A$5000,$A14)) | J14: =IF($BE14=0,NA(),H14+SUM($I$2:I14)) | K14: =IF($BE14=0,"",SUMIFS(Entries!$D$2:$D$5000,Entries!$C$2:$C$5000,"Income",Entries!$A$2:$A$5000,">="&EDATE($A14,-11),Entries!$A$2:$A$5000,"<="&$A14)/12) | L14: =IF($BE14=0,"",(SUMIFS(Entries!$D$2:$D$5000,Entries!$C$2:$C$5000,"Actual",Entries!$A$2:$A$5000,">="&EDATE($A14,-11),Entries!$A$2:$A$5000,"<="&$A14)+SUMIFS(Entries!$D$2:$D$5000,Entries!$C$2:$C$5000,"One-off",Entries!$A$2:$A$5000,">="&EDATE($A14,-11),Entries!$A$2:$A$5000,"<="&$A14))/12) | M14: =IF($BE14=0,NA(),IFERROR((K14-L14)/K14,0)) | O14: =IF(OR(O$1="",$BE14=0),"",SUMIFS(Entries!$D$2:$D$5000,Entries!$C$2:$C$5000,"Actual",Entries!$A$2:$A$5000,$A14,Entries!$B$2:$B$5000,O$1)) | P14: =IF(OR(P$1="",$BE14=0),"",SUMIFS(Entries!$D$2:$D$5000,Entries!$C$2:$C$5000,"Actual",Entries!$A$2:$A$5000,$A14,Entries!$B$2:$B$5000,P$1)) | Q14: =IF(OR(Q$1="",$BE14=0),"",SUMIFS(Entries!$D$2:$D$5000,Entries!$C$2:$C$5000,"Actual",Entries!$A$2:$A$5000,$A14,Entries!$B$2:$B$5000,Q$1)) | R14: =IF(OR(R$1="",$BE14=0),"",SUMIFS(Entries!$D$2:$D$5000,Entries!$C$2:$C$5000,"Actual",Entries!$A$2:$A$5000,$A14,Entries!$B$2:$B$5000,R$1)) | S14: =IF(OR(S$1="",$BE14=0),"",SUMIFS(Entries!$D$2:$D$5000,Entries!$C$2:$C$5000,"Actual",Entries!$A$2:$A$5000,$A14,Entries!$B$2:$B$5000,S$1)) | T14: =IF(OR(T$1="",$BE14=0),"",SUMIFS(Entries!$D$2:$D$5000,Entries!$C$2:$C$5000,"Actual",Entries!$A$2:$A$5000,$A14,Entries!$B$2:$B$5000,T$1)) | U14: =IF(OR(U$1="",$BE14=0),"",SUMIFS(Entries!$D$2:$D$5000,Entries!$C$2:$C$5000,"Actual",Entries!$A$2:$A$5000,$A14,Entries!$B$2:$B$5000,U$1)) | V14: =IF(OR(V$1="",$BE14=0),"",SUMIFS(Entries!$D$2:$D$5000,Entries!$C$2:$C$5000,"Actual",Entries!$A$2:$A$5000,$A14,Entries!$B$2:$B$5000,V$1)) | ... AH14: =IF(OR(AH$1="",$BE14=0),"",SUMIFS(Entries!$D$2:$D$5000,Entries!$C$2:$C$5000,"Actual",Entries!$A$2:$A$5000,$A14,Entries!$B$2:$B$5000,AH$1)) | AJ14: =IF(OR(AJ$1="",$BE14=0),"",IFERROR(LOOKUP(2,1/((Budgets!$A$2:$A$200=AJ$1)*(Budgets!$B$2:$B$200<=$A14)),Budgets!$C$2:$C$200),0)) | AK14: =IF(OR(AK$1="",$BE14=0),"",IFERROR(LOOKUP(2,1/((Budgets!$A$2:$A$200=AK$1)*(Budgets!$B$2:$B$200<=$A14)),Budgets!$C$2:$C$200),0)) | AL14: =IF(OR(AL$1="",$BE14=0),"",IFERROR(LOOKUP(2,1/((Budgets!$A$2:$A$200=AL$1)*(Budgets!$B$2:$B$200<=$A14)),Budgets!$C$2:$C$200),0)) | AM14: =IF(OR(AM$1="",$BE14=0),"",IFERROR(LOOKUP(2,1/((Budgets!$A$2:$A$200=AM$1)*(Budgets!$B$2:$B$200<=$A14)),Budgets!$C$2:$C$200),0)) | AN14: =IF(OR(AN$1="",$BE14=0),"",IFERROR(LOOKUP(2,1/((Budgets!$A$2:$A$200=AN$1)*(Budgets!$B$2:$B$200<=$A14)),Budgets!$C$2:$C$200),0)) | AO14: =IF(OR(AO$1="",$BE14=0),"",IFERROR(LOOKUP(2,1/((Budgets!$A$2:$A$200=AO$1)*(Budgets!$B$2:$B$200<=$A14)),Budgets!$C$2:$C$200),0)) | AP14: =IF(OR(AP$1="",$BE14=0),"",IFERROR(LOOKUP(2,1/((Budgets!$A$2:$A$200=AP$1)*(Budgets!$B$2:$B$200<=$A14)),Budgets!$C$2:$C$200),0)) | AQ14: =IF(OR(AQ$1="",$BE14=0),"",IFERROR(LOOKUP(2,1/((Budgets!$A$2:$A$200=AQ$1)*(Budgets!$B$2:$B$200<=$A14)),Budgets!$C$2:$C$200),0)) | ... BC14: =IF(OR(BC$1="",$BE14=0),"",IFERROR(LOOKUP(2,1/((Budgets!$A$2:$A$200=BC$1)*(Budgets!$B$2:$B$200<=$A14)),Budgets!$C$2:$C$200),0)) | BE14: =COUNTIFS(Entries!$A$2:$A$5000,$A14)
A15: 39845 | B15: =IF($BE15=0,NA(),SUMIFS(Entries!$D$2:$D$5000,Entries!$C$2:$C$5000,"Income",Entries!$A$2:$A$5000,$A15)) | C15: =IF($BE15=0,"",SUMIFS(Entries!$D$2:$D$5000,Entries!$C$2:$C$5000,"Actual",Entries!$A$2:$A$5000,$A15)) | D15: =IF($BE15=0,"",SUMIFS(Entries!$D$2:$D$5000,Entries!$C$2:$C$5000,"One-off",Entries!$A$2:$A$5000,$A15)) | E15: =IF($BE15=0,NA(),C15+D15) | F15: =IF($BE15=0,"",SUM(AJ15:BC15)) | G15: =IF($BE15=0,"",B15-E15) | H15: =IF($BE15=0,"",SUM($G$2:G15)) | I15: =IF($BE15=0,"",SUMIFS(Entries!$F$2:$F$5000,Entries!$A$2:$A$5000,$A15)) | J15: =IF($BE15=0,NA(),H15+SUM($I$2:I15)) | K15: =IF($BE15=0,"",SUMIFS(Entries!$D$2:$D$5000,Entries!$C$2:$C$5000,"Income",Entries!$A$2:$A$5000,">="&EDATE($A15,-11),Entries!$A$2:$A$5000,"<="&$A15)/12) | L15: =IF($BE15=0,"",(SUMIFS(Entries!$D$2:$D$5000,Entries!$C$2:$C$5000,"Actual",Entries!$A$2:$A$5000,">="&EDATE($A15,-11),Entries!$A$2:$A$5000,"<="&$A15)+SUMIFS(Entries!$D$2:$D$5000,Entries!$C$2:$C$5000,"One-off",Entries!$A$2:$A$5000,">="&EDATE($A15,-11),Entries!$A$2:$A$5000,"<="&$A15))/12) | M15: =IF($BE15=0,NA(),IFERROR((K15-L15)/K15,0)) | O15: =IF(OR(O$1="",$BE15=0),"",SUMIFS(Entries!$D$2:$D$5000,Entries!$C$2:$C$5000,"Actual",Entries!$A$2:$A$5000,$A15,Entries!$B$2:$B$5000,O$1)) | P15: =IF(OR(P$1="",$BE15=0),"",SUMIFS(Entries!$D$2:$D$5000,Entries!$C$2:$C$5000,"Actual",Entries!$A$2:$A$5000,$A15,Entries!$B$2:$B$5000,P$1)) | Q15: =IF(OR(Q$1="",$BE15=0),"",SUMIFS(Entries!$D$2:$D$5000,Entries!$C$2:$C$5000,"Actual",Entries!$A$2:$A$5000,$A15,Entries!$B$2:$B$5000,Q$1)) | R15: =IF(OR(R$1="",$BE15=0),"",SUMIFS(Entries!$D$2:$D$5000,Entries!$C$2:$C$5000,"Actual",Entries!$A$2:$A$5000,$A15,Entries!$B$2:$B$5000,R$1)) | S15: =IF(OR(S$1="",$BE15=0),"",SUMIFS(Entries!$D$2:$D$5000,Entries!$C$2:$C$5000,"Actual",Entries!$A$2:$A$5000,$A15,Entries!$B$2:$B$5000,S$1)) | T15: =IF(OR(T$1="",$BE15=0),"",SUMIFS(Entries!$D$2:$D$5000,Entries!$C$2:$C$5000,"Actual",Entries!$A$2:$A$5000,$A15,Entries!$B$2:$B$5000,T$1)) | U15: =IF(OR(U$1="",$BE15=0),"",SUMIFS(Entries!$D$2:$D$5000,Entries!$C$2:$C$5000,"Actual",Entries!$A$2:$A$5000,$A15,Entries!$B$2:$B$5000,U$1)) | V15: =IF(OR(V$1="",$BE15=0),"",SUMIFS(Entries!$D$2:$D$5000,Entries!$C$2:$C$5000,"Actual",Entries!$A$2:$A$5000,$A15,Entries!$B$2:$B$5000,V$1)) | ... AH15: =IF(OR(AH$1="",$BE15=0),"",SUMIFS(Entries!$D$2:$D$5000,Entries!$C$2:$C$5000,"Actual",Entries!$A$2:$A$5000,$A15,Entries!$B$2:$B$5000,AH$1)) | AJ15: =IF(OR(AJ$1="",$BE15=0),"",IFERROR(LOOKUP(2,1/((Budgets!$A$2:$A$200=AJ$1)*(Budgets!$B$2:$B$200<=$A15)),Budgets!$C$2:$C$200),0)) | AK15: =IF(OR(AK$1="",$BE15=0),"",IFERROR(LOOKUP(2,1/((Budgets!$A$2:$A$200=AK$1)*(Budgets!$B$2:$B$200<=$A15)),Budgets!$C$2:$C$200),0)) | AL15: =IF(OR(AL$1="",$BE15=0),"",IFERROR(LOOKUP(2,1/((Budgets!$A$2:$A$200=AL$1)*(Budgets!$B$2:$B$200<=$A15)),Budgets!$C$2:$C$200),0)) | AM15: =IF(OR(AM$1="",$BE15=0),"",IFERROR(LOOKUP(2,1/((Budgets!$A$2:$A$200=AM$1)*(Budgets!$B$2:$B$200<=$A15)),Budgets!$C$2:$C$200),0)) | AN15: =IF(OR(AN$1="",$BE15=0),"",IFERROR(LOOKUP(2,1/((Budgets!$A$2:$A$200=AN$1)*(Budgets!$B$2:$B$200<=$A15)),Budgets!$C$2:$C$200),0)) | AO15: =IF(OR(AO$1="",$BE15=0),"",IFERROR(LOOKUP(2,1/((Budgets!$A$2:$A$200=AO$1)*(Budgets!$B$2:$B$200<=$A15)),Budgets!$C$2:$C$200),0)) | AP15: =IF(OR(AP$1="",$BE15=0),"",IFERROR(LOOKUP(2,1/((Budgets!$A$2:$A$200=AP$1)*(Budgets!$B$2:$B$200<=$A15)),Budgets!$C$2:$C$200),0)) | AQ15: =IF(OR(AQ$1="",$BE15=0),"",IFERROR(LOOKUP(2,1/((Budgets!$A$2:$A$200=AQ$1)*(Budgets!$B$2:$B$200<=$A15)),Budgets!$C$2:$C$200),0)) | ... BC15: =IF(OR(BC$1="",$BE15=0),"",IFERROR(LOOKUP(2,1/((Budgets!$A$2:$A$200=BC$1)*(Budgets!$B$2:$B$200<=$A15)),Budgets!$C$2:$C$200),0)) | BE15: =COUNTIFS(Entries!$A$2:$A$5000,$A15)
A16: 39873 | B16: =IF($BE16=0,NA(),SUMIFS(Entries!$D$2:$D$5000,Entries!$C$2:$C$5000,"Income",Entries!$A$2:$A$5000,$A16)) | C16: =IF($BE16=0,"",SUMIFS(Entries!$D$2:$D$5000,Entries!$C$2:$C$5000,"Actual",Entries!$A$2:$A$5000,$A16)) | D16: =IF($BE16=0,"",SUMIFS(Entries!$D$2:$D$5000,Entries!$C$2:$C$5000,"One-off",Entries!$A$2:$A$5000,$A16)) | E16: =IF($BE16=0,NA(),C16+D16) | F16: =IF($BE16=0,"",SUM(AJ16:BC16)) | G16: =IF($BE16=0,"",B16-E16) | H16: =IF($BE16=0,"",SUM($G$2:G16)) | I16: =IF($BE16=0,"",SUMIFS(Entries!$F$2:$F$5000,Entries!$A$2:$A$5000,$A16)) | J16: =IF($BE16=0,NA(),H16+SUM($I$2:I16)) | K16: =IF($BE16=0,"",SUMIFS(Entries!$D$2:$D$5000,Entries!$C$2:$C$5000,"Income",Entries!$A$2:$A$5000,">="&EDATE($A16,-11),Entries!$A$2:$A$5000,"<="&$A16)/12) | L16: =IF($BE16=0,"",(SUMIFS(Entries!$D$2:$D$5000,Entries!$C$2:$C$5000,"Actual",Entries!$A$2:$A$5000,">="&EDATE($A16,-11),Entries!$A$2:$A$5000,"<="&$A16)+SUMIFS(Entries!$D$2:$D$5000,Entries!$C$2:$C$5000,"One-off",Entries!$A$2:$A$5000,">="&EDATE($A16,-11),Entries!$A$2:$A$5000,"<="&$A16))/12) | M16: =IF($BE16=0,NA(),IFERROR((K16-L16)/K16,0)) | O16: =IF(OR(O$1="",$BE16=0),"",SUMIFS(Entries!$D$2:$D$5000,Entries!$C$2:$C$5000,"Actual",Entries!$A$2:$A$5000,$A16,Entries!$B$2:$B$5000,O$1)) | P16: =IF(OR(P$1="",$BE16=0),"",SUMIFS(Entries!$D$2:$D$5000,Entries!$C$2:$C$5000,"Actual",Entries!$A$2:$A$5000,$A16,Entries!$B$2:$B$5000,P$1)) | Q16: =IF(OR(Q$1="",$BE16=0),"",SUMIFS(Entries!$D$2:$D$5000,Entries!$C$2:$C$5000,"Actual",Entries!$A$2:$A$5000,$A16,Entries!$B$2:$B$5000,Q$1)) | R16: =IF(OR(R$1="",$BE16=0),"",SUMIFS(Entries!$D$2:$D$5000,Entries!$C$2:$C$5000,"Actual",Entries!$A$2:$A$5000,$A16,Entries!$B$2:$B$5000,R$1)) | S16: =IF(OR(S$1="",$BE16=0),"",SUMIFS(Entries!$D$2:$D$5000,Entries!$C$2:$C$5000,"Actual",Entries!$A$2:$A$5000,$A16,Entries!$B$2:$B$5000,S$1)) | T16: =IF(OR(T$1="",$BE16=0),"",SUMIFS(Entries!$D$2:$D$5000,Entries!$C$2:$C$5000,"Actual",Entries!$A$2:$A$5000,$A16,Entries!$B$2:$B$5000,T$1)) | U16: =IF(OR(U$1="",$BE16=0),"",SUMIFS(Entries!$D$2:$D$5000,Entries!$C$2:$C$5000,"Actual",Entries!$A$2:$A$5000,$A16,Entries!$B$2:$B$5000,U$1)) | V16: =IF(OR(V$1="",$BE16=0),"",SUMIFS(Entries!$D$2:$D$5000,Entries!$C$2:$C$5000,"Actual",Entries!$A$2:$A$5000,$A16,Entries!$B$2:$B$5000,V$1)) | ... AH16: =IF(OR(AH$1="",$BE16=0),"",SUMIFS(Entries!$D$2:$D$5000,Entries!$C$2:$C$5000,"Actual",Entries!$A$2:$A$5000,$A16,Entries!$B$2:$B$5000,AH$1)) | AJ16: =IF(OR(AJ$1="",$BE16=0),"",IFERROR(LOOKUP(2,1/((Budgets!$A$2:$A$200=AJ$1)*(Budgets!$B$2:$B$200<=$A16)),Budgets!$C$2:$C$200),0)) | AK16: =IF(OR(AK$1="",$BE16=0),"",IFERROR(LOOKUP(2,1/((Budgets!$A$2:$A$200=AK$1)*(Budgets!$B$2:$B$200<=$A16)),Budgets!$C$2:$C$200),0)) | AL16: =IF(OR(AL$1="",$BE16=0),"",IFERROR(LOOKUP(2,1/((Budgets!$A$2:$A$200=AL$1)*(Budgets!$B$2:$B$200<=$A16)),Budgets!$C$2:$C$200),0)) | AM16: =IF(OR(AM$1="",$BE16=0),"",IFERROR(LOOKUP(2,1/((Budgets!$A$2:$A$200=AM$1)*(Budgets!$B$2:$B$200<=$A16)),Budgets!$C$2:$C$200),0)) | AN16: =IF(OR(AN$1="",$BE16=0),"",IFERROR(LOOKUP(2,1/((Budgets!$A$2:$A$200=AN$1)*(Budgets!$B$2:$B$200<=$A16)),Budgets!$C$2:$C$200),0)) | AO16: =IF(OR(AO$1="",$BE16=0),"",IFERROR(LOOKUP(2,1/((Budgets!$A$2:$A$200=AO$1)*(Budgets!$B$2:$B$200<=$A16)),Budgets!$C$2:$C$200),0)) | AP16: =IF(OR(AP$1="",$BE16=0),"",IFERROR(LOOKUP(2,1/((Budgets!$A$2:$A$200=AP$1)*(Budgets!$B$2:$B$200<=$A16)),Budgets!$C$2:$C$200),0)) | AQ16: =IF(OR(AQ$1="",$BE16=0),"",IFERROR(LOOKUP(2,1/((Budgets!$A$2:$A$200=AQ$1)*(Budgets!$B$2:$B$200<=$A16)),Budgets!$C$2:$C$200),0)) | ... BC16: =IF(OR(BC$1="",$BE16=0),"",IFERROR(LOOKUP(2,1/((Budgets!$A$2:$A$200=BC$1)*(Budgets!$B$2:$B$200<=$A16)),Budgets!$C$2:$C$200),0)) | BE16: =COUNTIFS(Entries!$A$2:$A$5000,$A16)
