Workbook
Name ColumnTitle1: Loan[[#Headers],[Pmt no.]]
Name EndingBalance: -FV(InterestRate/12,PaymentNumber,-MonthlyPayment,LoanAmount)
Name HeaderRow: ROW('Loan Calculator'!$16:$16)
Name InterestAmt: -IPMT(InterestRate/12,PaymentNumber,NumberOfPayments,LoanAmount)
Name InterestRate: 'Loan Calculator'!$D$6
Name LastCol: COUNTA('Loan Calculator'!$16:$16)
Name LastRow: MATCH(9.99E+307,'Loan Calculator'!$B:$B)
Name LoanAmount: 'Loan Calculator'!$D$5
Name LoanIsGood: IF(LoanAmount*InterestRate*LoanYears*LoanStartDate>0,1,0)
Name LoanIsNotPaid: IF(PaymentNumber<=NumberOfPayments,1,0)
Name LoanStartDate: 'Loan Calculator'!$D$8
Name LoanValue: -FV(InterestRate/12,PaymentNumber-1,-MonthlyPayment,LoanAmount)
Name LoanYears: 'Loan Calculator'!$D$7
Name MonthlyPayment: -PMT(InterestRate/12,NumberOfPayments,LoanAmount)
Name NumberOfPayments: 'Loan Calculator'!$D$12
Name PaymentDate: DATE(YEAR(LoanStartDate),MONTH(LoanStartDate)+PaymentNumber,DAY(LoanStartDate))
Name PaymentNumber: ROW()-HeaderRow
Name Principal: -PPMT(InterestRate/12,PaymentNumber,NumberOfPayments,LoanAmount)
Name PrintArea_SET: OFFSET('Loan Calculator'!$B$2,,,LastRow,LastCol)
Name RowTitleRegion1..D6: 'Loan Calculator'!$B$5
Name RowTitleRegion2..H6: 'Loan Calculator'!$B$11
Name Total_Interest: 'Loan Calculator'!$D$13
Name TotalLoanCost: 'Loan Calculator'!$D$14

Sheet Start Here
B1: PERSONAL FINANCE TRACKER
B2: A free template that grows with you — from basic financial planning to full portfolio management.
B4: HOW THIS WORKBOOK IS ORGANISED
B5: The tabs are colour-coded by level. Start with GREEN, add BLUE when you're ready, and graduate to PURPLE. GREY tabs are the engine room — they calculate everything automatically. Every tab: yellow cells are yours to edit, everything else is formulas.
B7: LEVEL 1 — FOUNDATIONS · know where you stand (≈15 minutes)
B8: 1. Settings — your age, savings, growth & inflation assumptions, FX rates. Everything reads from here.
B9: 2. Balance Sheet — list your accounts, investments, CPF and property. It totals your net worth and allocation.
B10: 3. Cash Flow — one row per month: income and expenses. This measures your real savings rate.
B11: 4. Net Worth History — one row per month with your latest net worth (from Balance Sheet E68).
B12: ✓ Payoff: the Dashboard shows your net worth, asset allocation, emergency-fund months and savings-rate checks — red/amber/green.
B13: Heads-up: a few Balance Sheet lines pull from Insurance, Housing and the stock ledger (Levels 2–3), so sample values linger there until you reset those tabs too — see RESETTING THE SAMPLE DATA at the bottom of this sheet.
B14: LEVEL 2 — LIFE PLANNING · protect and project
... B63: The Dashboard, Stock Dashboard and all grey tabs update themselves — never edit those.

Sheet Dashboard
A1: DASHBOARD
A2: A live snapshot. Numbers flow from the other tabs — update those and this refreshes automatically.
A4: NET WORTH | D4: ASSET ALLOCATION
A5: Net Worth | B5: ='Balance Sheet'!E68 -> 1225984.7 | D5: Class | E5: Value
A6: Assets (excl. home & car) | B6: ='Balance Sheet'!B68 -> 952364.44 | D6: ='Balance Sheet'!J32 -> Cash | E6: ='Balance Sheet'!K32 -> 137500
A7: Total Assets | B7: ='Balance Sheet'!B67 -> 1822364.4 | D7: ='Balance Sheet'!J33 -> Investments (Cap Protected 2-3%) | E7: ='Balance Sheet'!K33 -> 317000
A8: Total Liabilities | B8: ='Balance Sheet'!E67 -> 596379.74 | D8: ='Balance Sheet'!J34 -> Crypto | E8: ='Balance Sheet'!K34 -> 13252.532
A9: Liquid / Emergency Cash | B9: ='Balance Sheet'!B18 -> 137500 | D9: ='Balance Sheet'!J35 -> Small Cap | E9: ='Balance Sheet'!K35 -> 8150
A10: Liquid as % of Net Worth | B10: =IFERROR('Balance Sheet'!B18/'Balance Sheet'!E68,"") -> 0.11215474 | D10: ='Balance Sheet'!J36 -> US/HK Growth | E10: ='Balance Sheet'!K36 -> 39594.911
D11: ='Balance Sheet'!J37 -> Reit/Dividend | E11: ='Balance Sheet'!K37 -> 38740
A12: RETIREMENT | D12: ='Balance Sheet'!J38 -> Bonds | E12: ='Balance Sheet'!K38 -> 40000
A13: Planned retirement age | B13: =Settings!B7 -> 60 | D13: ='Balance Sheet'!J39 -> Gold/Silver | E13: ='Balance Sheet'!K39 -> 78127
A14: Projected portfolio @ retirement (5%) | B14: =INDEX('Retirement Plan'!I15:I58,MATCH(Settings!B7,'Retirement Plan'!A15:A58,0)) -> 3794449.9 | D14: ='Balance Sheet'!J40 -> Commodities | E14: ='Balance Sheet'!K40 -> 0
A15: Projected dividend income/yr (5%) | B15: =INDEX('Retirement Plan'!K15:K58,MATCH(Settings!B7,'Retirement Plan'!A15:A58,0)) -> 101429.04 | D15: ='Balance Sheet'!J41 -> CPF OA (2.5%) | E15: ='Balance Sheet'!K41 -> 95000
A16: Target annual retirement sum | B16: =Settings!B18 -> 60000 | D16: ='Balance Sheet'!J42 -> CPF SA Medisave | E16: ='Balance Sheet'!K42 -> 180000
D17: ='Balance Sheet'!J43 -> Real Properties | E17: ='Balance Sheet'!K43 -> 244570.26
A18: INSURANCE | D18: ='Balance Sheet'!J44 -> Personal Loan to Friend | E18: ='Balance Sheet'!K44 -> 5000
A19: Life / death coverage | B19: =Insurance!B8 -> 710000
A20: Critical illness coverage | B20: =Insurance!B10 -> 410000
A21: Total annual premium | B21: =Insurance!B7 -> 5048.88
A22: Insurance cash value (in net worth) | B22: =Insurance!B5 -> 135000
A24: HOUSING
A25: Property value (your share) | B25: =Housing!B20 -> 825000
A26: Mortgage (your share) | B26: =Housing!B21 -> 580429.74
A27: Home equity (your share) | B27: =Housing!B22 -> 244570.26
A29: STATUS CHECKS
A30: Emergency fund (months of expenses) | B30: =IFERROR('Balance Sheet'!B18/Settings!B31,"") -> 27.5 | C30: target ≥ 6
A31: Top holding concentration (stocks) | B31: ='Stock Dashboard'!B12 -> 0.43925024 | C31: target < 10%
A32: FI number (target income ÷ safe withdrawal rate) | B32: =IFERROR(Settings!B18/Settings!B32,"") -> 1500000
A33: Retirement readiness (proj @5% ÷ FI number) | B33: =IFERROR(B14/B32,"") -> 2.5296333 | C33: target ≥ 100%
A34: Actual savings rate (Cash Flow, last 12m) | B34: ='Cash Flow'!$B$7 -> 0.375
A35: Actual annual savings (Cash Flow) | B35: ='Cash Flow'!$B$8 -> 36000 | C35: ="plan: "&TEXT(Settings!$B$8,"$#,##0") -> plan: $30,000

Sheet Settings
A1: SETTINGS & ASSUMPTIONS
A2: Edit the yellow cells. The rest of the workbook reads its assumptions from here.
A4: YOUR PROFILE
A5: Current age | B5: 42
A6: Current year (projection base) | B6: 2026
A7: Planned retirement age | B7: 60
A8: Annual savings ($/yr) | B8: 30000
A10: RETURN ASSUMPTIONS
A11: Annual inflation | B11: 0.025
A12: Conservative growth | B12: 0.03
A13: Moderate growth | B13: 0.05
A14: Aggressive growth | B14: 0.08
A15: Dividend yield (on portfolio) | B15: 0.04
A17: RETIREMENT TARGETS (Singapore)
A18: Target annual retirement sum ($/yr) | B18: 60000
A19: Reserve for housing / HDB ($) | B19: 330000
A21: FX TO SGD (single source of truth — the Prices tab reads these)
A22: USD -> SGD | B22: 1.2928081
A23: HKD -> SGD | B23: 0.16489949
A25: Notes:
A26: CPF (Central Provident Fund), SRS (Supplementary Retirement Scheme), SSB (Singapore Savings Bonds),
A27: BSD (Buyer Stamp Duty), HDB (public housing). Replace with your local equivalents if you are outside Singapore.
A28: ‘Current year (projection base)’ = the year that matches your current age above; the Retirement Plan projection counts up from it to age 85.
A30: SPENDING & RETIREMENT TARGETS
A31: Monthly household expenses ($/mth) | B31: 5000
A32: Safe withdrawal rate (for FI number) | B32: 0.04
A34: CHILD / EDUCATION ASSUMPTIONS (used by Balance Sheet liabilities)
A35: Education inflation | B35: 0.03
A36: Years until university | B36: 14
A37: Degree cost per year (today's $) | B37: 33000
A38: Degree length (years) | B38: 5
A39: Allowance during studies ($/mth) | B39: 1500

Sheet Balance Sheet
A1: As at today — values update live from the other tabs
A2: Assets | D2: Liabilities and Net Worth
A4: Liquid Assets | D4: Current Liabilities
A5: POSB Cash | B5: 8500 | D5: OCBC Credit Balance | E5: 1800
A6: e$aver (Closed) | B6: 0 | D6: Maribank + POSB | E6: 950
A7: XtraSaver (Closed) | B7: 0 | D7: UOB | E7: 1200
A8: DASH by Standchart (Closed) | B8: 0
A9: Maybank | B9: 15000 | D9: Total | E9: =SUM(E5:E7) -> 3950
A10: Trust Bank | B10: 12000
A11: Super Salary Acct (Closed) | B11: 0
A12: Maribank + Funds | B12: 20000
A13: POSB Joint | B13: 6500
A14: UOB ONE Account | B14: 38000
A15: UOB Savings | B15: 0
A16: OCBC 360 + Joint Account | B16: 28000
A17: DBS Multicurrency + MooMoo Cash Account + Webull Cash | B17: 9500
A18: Total | B18: =SUM(B5:B17) -> 137500
D19: Long Term Liabilities
D20: Child Savings | E20: 12000
A21: Investments (Cap Protected 2-3%) | D21: University Study Fund | E21: 0
A22: AIA Endowment Deposit (4% p.a.) | B22: =Insurance!H21 -> 0 | D22: UOB Home Loan | E22: =Housing!B21 -> 580429.74
A23: Prudential Savings (Projected $100,000 @ 52) | B23: =Insurance!H18 -> 60000
A24: UOB/Prudential Savings (Projected $46,000 @ 52) | B24: =Insurance!H19 -> 28000 | D24: Total | E24: =SUM(E20:E22) -> 592429.74
A25: Prudential Saving (2%PA till 2022 using SRS) (Closed) | D25: Child University Fund (e.g. degree @ $33k/yr) | E25: =((1+Settings!$B$35)^Settings!$B$36)*Settings!$B$37*Settings!$B$38 -> 249577.3
A26: NTUC Savings/Insurance (Projected $40,000 @ 55) | B26: =Insurance!H15+Insurance!H16 -> 22000 | D26: Child Allowance during studies (e.g. $1,500/mth) | E26: =((1+Settings!$B$35)^Settings!$B$36)*Settings!$B$39*12*Settings!$B$38 -> 136133.08
A27: SRS Account (Supplementary Retirement Scheme) | B27: 120000
A28: CPF Cash Top-ups for Family Members (tax relief) | B28: 35000
A29: Child Development Account (CDA) Contributions | B29: 9000
A30: Singapore Savings Bond (1.89% coupon, using SRS) | B30: 18000 | J30: Asset Allocation
A31: Temasek Bond (2.7% coupon) | K31: Amount | L31: Percentage
A32: AIA ILP | B32: =Insurance!H20 -> 25000 | J32: Cash | K32: =B18 -> 137500 | L32: =K32/SUM($K$32:$K$44) -> 0.11487678
A33: Total | B33: =SUM(B22:B32) -> 317000 | J33: =$A$21 -> Investments (Cap Protected 2-3%) | K33: =$B$33 -> 317000 | L33: =K33/SUM($K$32:$K$44) -> 0.26484318
J34: =A37 -> Crypto | K34: =$B$37 -> 13252.532 | L34: =K34/SUM($K$32:$K$44) -> 0.011072059
A35: Equities/Crypto/High Risk Loans | J35: =A40 -> Small Cap | K35: =$B$40 -> 8150 | L35: =K35/SUM($K$32:$K$44) -> 0.0068090598
A36: Personal Loan to Friend | B36: 5000 | J36: =A38 -> US/HK Growth | K36: =$B$38 -> 39594.911 | L36: =K36/SUM($K$32:$K$44) -> 0.03308026
A37: =Shares!R7 -> Crypto | B37: =Shares!S7 -> 13252.532 | J37: =A39 -> Reit/Dividend | K37: =$B$39 -> 38740 | L37: =K37/SUM($K$32:$K$44) -> 0.032366009 | M37: =SUM(L34:L37) -> 0.083327388 | N37: <- high-risk subtotal (rows 34-37)
A38: =Shares!R3 -> US/HK Growth | B38: =Shares!S3 -> 39594.911 | J38: Bonds | K38: =$B$46 -> 40000 | L38: =K38/SUM($K$32:$K$44) -> 0.033418698
A39: =Shares!R4 -> Reit/Dividend | B39: =Shares!S4 -> 38740 | J39: Gold/Silver | K39: =B48 -> 78127 | L39: =K39/SUM($K$32:$K$44) -> 0.065272566
A40: =Shares!R5 -> Small Cap | B40: =Shares!S5 -> 8150 | J40: =A49 -> Commodities | K40: =B49 -> 0 | L40: =K40/SUM($K$32:$K$44) -> 0
A41: Total | B41: =SUM(B36:B40) -> 104737.44 | J41: =$A$53 -> CPF OA (2.5%) | K41: =$B$53 -> 95000 | L41: =K41/SUM($K$32:$K$44) -> 0.079369409
...

Sheet Cash Flow
A1: CASH FLOW (monthly income & spending — your measured savings rate)
A2: One row per month, yellow cells only. The averages below use your last 12 months of entries and are compared against the plan numbers in Settings.
A4: ACTUALS (last 12 months of entries)
A5: Average monthly take-home income | B5: =IFERROR(AVERAGEIFS($B$13:$B$60,$A$13:$A$60,">"&EDATE(TODAY(),-12)),"") -> 8000
A6: Average monthly expenses | B6: =IFERROR(AVERAGEIFS($E$13:$E$60,$A$13:$A$60,">"&EDATE(TODAY(),-12)),"") -> 5000 | C6: ="plan (Settings): "&TEXT(Settings!$B$31,"$#,##0") -> plan (Settings): $5,000
A7: Average savings rate | B7: =IFERROR(1-B6/B5,"") -> 0.375
A8: Implied annual savings (actual) | B8: =IFERROR((B5-B6)*12,"") -> 36000 | C8: ="plan (Settings): "&TEXT(Settings!$B$8,"$#,##0") -> plan (Settings): $30,000
A10: Tip: once a few months are entered, consider updating the yellow plan numbers in Settings to match reality.
A12: Month | B12: Take-home income | C12: Fixed expenses | D12: Variable expenses | E12: Total expenses | F12: Saved | G12: Savings rate | H12: Notes
A13: 46174 | B13: 8000 | C13: 3500 | D13: 1500 | E13: =IF($A13="","",$C13+$D13) -> 5000 | F13: =IF($A13="","",$B13-$E13) -> 3000 | G13: =IF(OR($A13="",$B13="",$B13=0),"",$F13/$B13) -> 0.375 | H13: [Sample] replace with your own
E14: =IF($A14="","",$C14+$D14) | F14: =IF($A14="","",$B14-$E14) | G14: =IF(OR($A14="",$B14="",$B14=0),"",$F14/$B14)
E15: =IF($A15="","",$C15+$D15) | F15: =IF($A15="","",$B15-$E15) | G15: =IF(OR($A15="",$B15="",$B15=0),"",$F15/$B15)
E16: =IF($A16="","",$C16+$D16) | F16: =IF($A16="","",$B16-$E16) | G16: =IF(OR($A16="",$B16="",$B16=0),"",$F16/$B16)
E17: =IF($A17="","",$C17+$D17) | F17: =IF($A17="","",$B17-$E17) | G17: =IF(OR($A17="",$B17="",$B17=0),"",$F17/$B17)
E18: =IF($A18="","",$C18+$D18) | F18: =IF($A18="","",$B18-$E18) | G18: =IF(OR($A18="",$B18="",$B18=0),"",$F18/$B18)
E19: =IF($A19="","",$C19+$D19) | F19: =IF($A19="","",$B19-$E19) | G19: =IF(OR($A19="",$B19="",$B19=0),"",$F19/$B19)
E20: =IF($A20="","",$C20+$D20) | F20: =IF($A20="","",$B20-$E20) | G20: =IF(OR($A20="",$B20="",$B20=0),"",$F20/$B20)
E21: =IF($A21="","",$C21+$D21) | F21: =IF($A21="","",$B21-$E21) | G21: =IF(OR($A21="",$B21="",$B21=0),"",$F21/$B21)
E22: =IF($A22="","",$C22+$D22) | F22: =IF($A22="","",$B22-$E22) | G22: =IF(OR($A22="",$B22="",$B22=0),"",$F22/$B22)
E23: =IF($A23="","",$C23+$D23) | F23: =IF($A23="","",$B23-$E23) | G23: =IF(OR($A23="",$B23="",$B23=0),"",$F23/$B23)
E24: =IF($A24="","",$C24+$D24) | F24: =IF($A24="","",$B24-$E24) | G24: =IF(OR($A24="",$B24="",$B24=0),"",$F24/$B24)
E25: =IF($A25="","",$C25+$D25) | F25: =IF($A25="","",$B25-$E25) | G25: =IF(OR($A25="",$B25="",$B25=0),"",$F25/$B25)
... E60: =IF($A60="","",$C60+$D60) | F60: =IF($A60="","",$B60-$E60) | G60: =IF(OR($A60="",$B60="",$B60=0),"",$F60/$B60)

Sheet Net Worth History
A1: NET WORTH HISTORY
A2: Each month, record your net worth (copy the value from Balance Sheet cell E68). Add new rows at the bottom; the formulas will extend if you copy them down. (Sample rows are quarterly just to demonstrate the formulas — monthly is better.)
A4: Date | B4: Net Worth | C4: MoM Change | D4: YoY Change | E4: YoY % | F4: 12-mo Avg (MoM) | G4: Notes
A5: 45627 | B5: 1050000 | G5: Starting point
A6: 45717 | B6: 1082000 | C6: =IF(OR($A6="",$B6=""),"",IF($B5="","",$B6-$B5)) -> 32000 | D6: =IF(OR($A6="",$B6=""),"",IFERROR($B6-LOOKUP(EDATE($A6,-12),$A$5:$A5,$B$5:$B5),"")) | E6: =IF($D6="","",IFERROR($D6/($B6-$D6),"")) | F6: =IF(OR($A6="",$B6=""),"",IFERROR(AVERAGEIFS($C$5:$C6,$A$5:$A6,">"&EDATE($A6,-12),$A$5:$A6,"<="&$A6),"")) -> 32000
A7: 45809 | B7: 1068000 | C7: =IF(OR($A7="",$B7=""),"",IF($B6="","",$B7-$B6)) -> -14000 | D7: =IF(OR($A7="",$B7=""),"",IFERROR($B7-LOOKUP(EDATE($A7,-12),$A$5:$A6,$B$5:$B6),"")) | E7: =IF($D7="","",IFERROR($D7/($B7-$D7),"")) | F7: =IF(OR($A7="",$B7=""),"",IFERROR(AVERAGEIFS($C$5:$C7,$A$5:$A7,">"&EDATE($A7,-12),$A$5:$A7,"<="&$A7),"")) -> 9000 | G7: Market dip
A8: 45901 | B8: 1120000 | C8: =IF(OR($A8="",$B8=""),"",IF($B7="","",$B8-$B7)) -> 52000 | D8: =IF(OR($A8="",$B8=""),"",IFERROR($B8-LOOKUP(EDATE($A8,-12),$A$5:$A7,$B$5:$B7),"")) | E8: =IF($D8="","",IFERROR($D8/($B8-$D8),"")) | F8: =IF(OR($A8="",$B8=""),"",IFERROR(AVERAGEIFS($C$5:$C8,$A$5:$A8,">"&EDATE($A8,-12),$A$5:$A8,"<="&$A8),"")) -> 23333.333
A9: 45992 | B9: 1168000 | C9: =IF(OR($A9="",$B9=""),"",IF($B8="","",$B9-$B8)) -> 48000 | D9: =IF(OR($A9="",$B9=""),"",IFERROR($B9-LOOKUP(EDATE($A9,-12),$A$5:$A8,$B$5:$B8),"")) -> 118000 | E9: =IF($D9="","",IFERROR($D9/($B9-$D9),"")) -> 0.11238095 | F9: =IF(OR($A9="",$B9=""),"",IFERROR(AVERAGEIFS($C$5:$C9,$A$5:$A9,">"&EDATE($A9,-12),$A$5:$A9,"<="&$A9),"")) -> 29500 | G9: Year-end bonus saved
A10: 46082 | B10: 1196000 | C10: =IF(OR($A10="",$B10=""),"",IF($B9="","",$B10-$B9)) -> 28000 | D10: =IF(OR($A10="",$B10=""),"",IFERROR($B10-LOOKUP(EDATE($A10,-12),$A$5:$A9,$B$5:$B9),"")) -> 114000 | E10: =IF($D10="","",IFERROR($D10/($B10-$D10),"")) -> 0.10536044 | F10: =IF(OR($A10="",$B10=""),"",IFERROR(AVERAGEIFS($C$5:$C10,$A$5:$A10,">"&EDATE($A10,-12),$A$5:$A10,"<="&$A10),"")) -> 28500
A11: 46174 | B11: 1224000 | C11: =IF(OR($A11="",$B11=""),"",IF($B10="","",$B11-$B10)) -> 28000 | D11: =IF(OR($A11="",$B11=""),"",IFERROR($B11-LOOKUP(EDATE($A11,-12),$A$5:$A10,$B$5:$B10),"")) -> 156000 | E11: =IF($D11="","",IFERROR($D11/($B11-$D11),"")) -> 0.14606742 | F11: =IF(OR($A11="",$B11=""),"",IFERROR(AVERAGEIFS($C$5:$C11,$A$5:$A11,">"&EDATE($A11,-12),$A$5:$A11,"<="&$A11),"")) -> 39000
C12: =IF(OR($A12="",$B12=""),"",IF($B11="","",$B12-$B11)) | D12: =IF(OR($A12="",$B12=""),"",IFERROR($B12-LOOKUP(EDATE($A12,-12),$A$5:$A11,$B$5:$B11),"")) | E12: =IF($D12="","",IFERROR($D12/($B12-$D12),"")) | F12: =IF(OR($A12="",$B12=""),"",IFERROR(AVERAGEIFS($C$5:$C12,$A$5:$A12,">"&EDATE($A12,-12),$A$5:$A12,"<="&$A12),""))
C13: =IF(OR($A13="",$B13=""),"",IF($B12="","",$B13-$B12)) | D13: =IF(OR($A13="",$B13=""),"",IFERROR($B13-LOOKUP(EDATE($A13,-12),$A$5:$A12,$B$5:$B12),"")) | E13: =IF($D13="","",IFERROR($D13/($B13-$D13),"")) | F13: =IF(OR($A13="",$B13=""),"",IFERROR(AVERAGEIFS($C$5:$C13,$A$5:$A13,">"&EDATE($A13,-12),$A$5:$A13,"<="&$A13),""))
C14: =IF(OR($A14="",$B14=""),"",IF($B13="","",$B14-$B13)) | D14: =IF(OR($A14="",$B14=""),"",IFERROR($B14-LOOKUP(EDATE($A14,-12),$A$5:$A13,$B$5:$B13),"")) | E14: =IF($D14="","",IFERROR($D14/($B14-$D14),"")) | F14: =IF(OR($A14="",$B14=""),"",IFERROR(AVERAGEIFS($C$5:$C14,$A$5:$A14,">"&EDATE($A14,-12),$A$5:$A14,"<="&$A14),""))
C15: =IF(OR($A15="",$B15=""),"",IF($B14="","",$B15-$B14)) | D15: =IF(OR($A15="",$B15=""),"",IFERROR($B15-LOOKUP(EDATE($A15,-12),$A$5:$A14,$B$5:$B14),"")) | E15: =IF($D15="","",IFERROR($D15/($B15-$D15),"")) | F15: =IF(OR($A15="",$B15=""),"",IFERROR(AVERAGEIFS($C$5:$C15,$A$5:$A15,">"&EDATE($A15,-12),$A$5:$A15,"<="&$A15),""))
C16: =IF(OR($A16="",$B16=""),"",IF($B15="","",$B16-$B15)) | D16: =IF(OR($A16="",$B16=""),"",IFERROR($B16-LOOKUP(EDATE($A16,-12),$A$5:$A15,$B$5:$B15),"")) | E16: =IF($D16="","",IFERROR($D16/($B16-$D16),"")) | F16: =IF(OR($A16="",$B16=""),"",IFERROR(AVERAGEIFS($C$5:$C16,$A$5:$A16,">"&EDATE($A16,-12),$A$5:$A16,"<="&$A16),""))
C17: =IF(OR($A17="",$B17=""),"",IF($B16="","",$B17-$B16)) | D17: =IF(OR($A17="",$B17=""),"",IFERROR($B17-LOOKUP(EDATE($A17,-12),$A$5:$A16,$B$5:$B16),"")) | E17: =IF($D17="","",IFERROR($D17/($B17-$D17),"")) | F17: =IF(OR($A17="",$B17=""),"",IFERROR(AVERAGEIFS($C$5:$C17,$A$5:$A17,">"&EDATE($A17,-12),$A$5:$A17,"<="&$A17),""))
C18: =IF(OR($A18="",$B18=""),"",IF($B17="","",$B18-$B17)) | D18: =IF(OR($A18="",$B18=""),"",IFERROR($B18-LOOKUP(EDATE($A18,-12),$A$5:$A17,$B$5:$B17),"")) | E18: =IF($D18="","",IFERROR($D18/($B18-$D18),"")) | F18: =IF(OR($A18="",$B18=""),"",IFERROR(AVERAGEIFS($C$5:$C18,$A$5:$A18,">"&EDATE($A18,-12),$A$5:$A18,"<="&$A18),""))
C19: =IF(OR($A19="",$B19=""),"",IF($B18="","",$B19-$B18)) | D19: =IF(OR($A19="",$B19=""),"",IFERROR($B19-LOOKUP(EDATE($A19,-12),$A$5:$A18,$B$5:$B18),"")) | E19: =IF($D19="","",IFERROR($D19/($B19-$D19),"")) | F19: =IF(OR($A19="",$B19=""),"",IFERROR(AVERAGEIFS($C$5:$C19,$A$5:$A19,">"&EDATE($A19,-12),$A$5:$A19,"<="&$A19),""))
C20: =IF(OR($A20="",$B20=""),"",IF($B19="","",$B20-$B19)) | D20: =IF(OR($A20="",$B20=""),"",IFERROR($B20-LOOKUP(EDATE($A20,-12),$A$5:$A19,$B$5:$B19),"")) | E20: =IF($D20="","",IFERROR($D20/($B20-$D20),"")) | F20: =IF(OR($A20="",$B20=""),"",IFERROR(AVERAGEIFS($C$5:$C20,$A$5:$A20,">"&EDATE($A20,-12),$A$5:$A20,"<="&$A20),""))
C21: =IF(OR($A21="",$B21=""),"",IF($B20="","",$B21-$B20)) | D21: =IF(OR($A21="",$B21=""),"",IFERROR($B21-LOOKUP(EDATE($A21,-12),$A$5:$A20,$B$5:$B20),"")) | E21: =IF($D21="","",IFERROR($D21/($B21-$D21),"")) | F21: =IF(OR($A21="",$B21=""),"",IFERROR(AVERAGEIFS($C$5:$C21,$A$5:$A21,">"&EDATE($A21,-12),$A$5:$A21,"<="&$A21),""))
C22: =IF(OR($A22="",$B22=""),"",IF($B21="","",$B22-$B21)) | D22: =IF(OR($A22="",$B22=""),"",IFERROR($B22-LOOKUP(EDATE($A22,-12),$A$5:$A21,$B$5:$B21),"")) | E22: =IF($D22="","",IFERROR($D22/($B22-$D22),"")) | F22: =IF(OR($A22="",$B22=""),"",IFERROR(AVERAGEIFS($C$5:$C22,$A$5:$A22,">"&EDATE($A22,-12),$A$5:$A22,"<="&$A22),""))
C23: =IF(OR($A23="",$B23=""),"",IF($B22="","",$B23-$B22)) | D23: =IF(OR($A23="",$B23=""),"",IFERROR($B23-LOOKUP(EDATE($A23,-12),$A$5:$A22,$B$5:$B22),"")) | E23: =IF($D23="","",IFERROR($D23/($B23-$D23),"")) | F23: =IF(OR($A23="",$B23=""),"",IFERROR(AVERAGEIFS($C$5:$C23,$A$5:$A23,">"&EDATE($A23,-12),$A$5:$A23,"<="&$A23),""))
... C40: =IF(OR($A40="",$B40=""),"",IF($B39="","",$B40-$B39)) | D40: =IF(OR($A40="",$B40=""),"",IFERROR($B40-LOOKUP(EDATE($A40,-12),$A$5:$A39,$B$5:$B39),"")) | E40: =IF($D40="","",IFERROR($D40/($B40-$D40),"")) | F40: =IF(OR($A40="",$B40=""),"",IFERROR(AVERAGEIFS($C$5:$C40,$A$5:$A40,">"&EDATE($A40,-12),$A$5:$A40,"<="&$A40),""))

Sheet Insurance
A1: INSURANCE
A2: One row per policy. Yellow cells = type your own number. Current cash/surrender value flows to the Balance Sheet; projected maturity value feeds the Retirement Plan. Coverage is protection, not an asset.
A4: SUMMARY
A5: Current cash / surrender value (asset today) | B5: =SUM(H15:H21) -> 135000 | C5: <- flows to the Balance Sheet
A6: Projected maturity value (future) | B6: =SUM(I15:I21) -> 237422 | C6: <- feeds the Retirement Plan
A7: Total annual premium | B7: =SUM(L15:L21) -> 5048.88
A8: Total life / death coverage | B8: =SUM(N15:N21) -> 710000
A9: Total TPD coverage | B9: =SUM(O15:O21) -> 710000
A10: Total critical illness coverage | B10: =SUM(P15:P21) -> 410000
A11: Number of policies | B11: =COUNTA(A15:A21) -> 7
A14: Policy | B14: Company | C14: Policy No. | D14: Plan Type / Name | E14: Category | F14: Commencement | G14: Maturity Age | H14: Current Cash / Surrender Value | I14: Projected Maturity Value | J14: Premium Amount | K14: Frequency | L14: Annual Premium | M14: Sum Assured (Basic) | N14: Death Benefit | O14: TPD Benefit | P14: Critical Illness Benefit | Q14: Remarks
A15: Policy 1 | B15: NTUC | C15: POL-0001 | D15: Living Policy (Whole Life) | E15: Protection | F15: 37012 | G15: 60 | H15: 10000 | I15: 39188 | J15: 33.1 | K15: Monthly | L15: =IF(K15="Monthly",J15*12,IF(K15="Quarterly",J15*4,J15)) -> 397.2 | M15: 20000 | N15: 20000 | O15: 20000 | P15: 20000 | Q15: Participating whole life. TPD: 10% of S/A+bonus yrs1-4, 60% yr5 (till age 60). Convertible to annuity @60 +5%. Hosp benefit $30/day.
A16: Policy 2 | B16: NTUC | C16: POL-0002 | D16: Living Policy (Whole Life) | E16: Protection | F16: 38987 | G16: 60 | H16: 12000 | I16: 42234 | J16: 62.3 | K16: Monthly | L16: =IF(K16="Monthly",J16*12,IF(K16="Quarterly",J16*4,J16)) -> 747.6 | M16: 30000 | N16: 30000 | O16: 30000 | P16: 30000 | Q16: Whole life + term rider 13/20 x $100k (till age 45). Disability income: TPD $6k/yr from 6th yr (till 65); Major illness $500/mth 20 yrs. Convertible to annuity @60 +5%.
A17: Policy 3 | B17: Aviva | C17: POL-C1 / POL-C2 | D17: Group Term Life + Living Care | E17: Term | F17: 40934 | G17: 65 | H17: 0 | I17: 0 | J17: 106.8 | K17: Monthly | L17: =IF(K17="Monthly",J17*12,IF(K17="Quarterly",J17*4,J17)) -> 1281.6 | M17: 600000 | N17: 600000 | O17: 600000 | P17: 300000 | Q17: Term to 65, no cash value. Critical illness $300k. Hosp benefit $120/day (day 11-30).
A18: Policy 4 | B18: Prudential | C18: POL-0004 | D18: PruSave (Endowment) | E18: Endowment/Savings | F18: 39499 | G18: 60 | H18: 60000 | I18: 110000 | J18: 218.54 | K18: Monthly | L18: =IF(K18="Monthly",J18*12,IF(K18="Quarterly",J18*4,J18)) -> 2622.48 | M18: 60000 | N18: 60000 | O18: 60000 | P18: 60000 | Q18: Endowment/savings plan. Projected maturity ~$110k @60. Convertible to annuity @60 +5%.
A19: Policy 5 | B19: Prudential | C19: (UOB/Pru) | D19: UOB/Prudential Savings | E19: Endowment/Savings | G19: 52 | H19: 28000 | I19: 46000 | K19: Monthly | L19: =IF(K19="Monthly",J19*12,IF(K19="Quarterly",J19*4,J19)) -> 0 | Q19: Savings plan projected ~$46k @52. Update premium/coverage from your policy document.
A20: Policy 6 | B20: AIA | C20: (ILP) | D20: Investment-Linked Policy | E20: Investment-Linked | H20: 25000 | K20: Monthly | L20: =IF(K20="Monthly",J20*12,IF(K20="Quarterly",J20*4,J20)) -> 0 | Q20: Market-linked policy; cash value moves with fund NAV. Not capital-guaranteed.
A21: Policy 7 | B21: AIA | C21: (Endowment) | D21: Endowment Deposit (4% p.a.) | E21: Endowment/Savings | H21: 0 | K21: Monthly | L21: =IF(K21="Monthly",J21*12,IF(K21="Quarterly",J21*4,J21)) -> 0 | Q21: AIA endowment deposit, ~4% p.a. Enter current surrender value when available.
A23: Notes: Cash/surrender value = what you'd realise if you cashed out today (the asset figure). Term/protection-only policies have no cash value. Add more policies on new rows below the table - the SUMMARY and linked sheets update automatically.

Sheet Housing
A1: HOUSING & MORTGAGE
A2: Yellow = type your own number. Loan terms & the full repayment schedule live on the Loan Calculator tab. Your ownership share of the property value and loan flows to the Balance Sheet.
A4: PROPERTY
A5: Current market value (100%) | B5: 1500000
A6: Original purchase price (100%) | B6: 1500000
A7: Purchase date | B7: 45658
A8: Your ownership share | B8: 0.55
A9: Spouse ownership share | B9: =1-B8 -> 0.45
A11: MORTGAGE (set loan terms on the Loan Calculator tab)
A12: Original loan amount | B12: ='Loan Calculator'!D5 -> 1125000
A13: Interest rate (p.a.) | B13: ='Loan Calculator'!D6 -> 0.02
A14: Loan tenure (years) | B14: ='Loan Calculator'!D7 -> 20
A15: Loan start date | B15: ='Loan Calculator'!D8 -> 45658
A16: Monthly repayment | B16: ='Loan Calculator'!D11 -> 5691.1875
A17: Outstanding balance (today, 100%) | B17: ='Loan Calculator'!D15 -> 1055326.8
A19: YOUR POSITION (flows to Balance Sheet)
A20: Property value - your share | B20: =B5*B8 -> 825000 | D20: <- Balance Sheet asset
A21: Outstanding loan - your share | B21: =B17*B8 -> 580429.74 | D21: <- Balance Sheet liability
A22: Home equity - your share | B22: =B20-B21 -> 244570.26
A23: Home equity - full (100%) | B23: =B5-B17 -> 444673.21
A25: PAYDOWN PLAN (optional target)
A26: Target loan balance (100%) | B26: 1000000
A27: Target date | B27: 47118
A28: Amount still to pay down (100%) | B28: =MAX(0,B17-B26) -> 55326.792
A29: - your share | B29: =B28*B8 -> 30429.736
A30: - spouse share | B30: =B28*B9 -> 24897.057
A31: Years to target (approx) | B31: =MAX(0,(B27-TODAY())/365) -> 2.4712329
A32: Annual paydown needed - your share | B32: =IFERROR(B29/B31,0) -> 12313.585
A34: CPF FUNDING (planning)
A35: Current CPF OA balance | B35: ='Balance Sheet'!B53 -> 95000
A36: CPF OA contribution / month | B36: 2200
A37: CPF OA contribution / year (13 mths) | B37: =B36*13 -> 28600
A38: Emergency CPF buffer to keep | B38: 236000
A39: CPF OA available after buffer | B39: =B35-B38 -> -141000
A41: PURCHASE FUNDING (one-time record of how the purchase was paid)
A42: Funding source | B42: Spouse (45%) | C42: Self (55%) | D42: Total
A43: CPF used | B43: 90000 | C43: 120000 | D43: =B43+C43 -> 210000
A44: Cash used | B44: 170000 | C44: 120000 | D44: =B44+C44 -> 290000
A45: Total upfront paid | B45: =SUM(B43:B44) -> 260000 | C45: =SUM(C43:C44) -> 240000 | D45: =SUM(D43:D44) -> 500000
A47: Note: 'Your Position' (rows 20-22) are the only figures used by the Balance Sheet. Paydown, CPF and purchase-funding sections are planning/records and do not affect net worth.

Sheet Loan Calculator
B2: Simple loan calculator | M2: Annual summary (auto-updates from the schedule below)
B4: Loan details | M4: Year | N4: Principal Paid | O4: Interest Paid | P4: Total Paid
C5: Loan amount | D5: 1125000 | M5: =YEAR($D$8) -> 2025 | N5: =SUMPRODUCT(($M5=YEAR($C$17:$C$256))*$F$17:$F$256) -> 42329.635 | O5: =SUMPRODUCT(($M5=YEAR($C$17:$C$256))*$H$17:$H$256) -> 20273.428 | P5: =N5+O5 -> 62603.063
C6: Annual interest rate | D6: 0.02 | M6: =M5+1 -> 2026 | N6: =SUMPRODUCT(($M6=YEAR($C$17:$C$256))*$F$17:$F$256) -> 47070.768 | O6: =SUMPRODUCT(($M6=YEAR($C$17:$C$256))*$H$17:$H$256) -> 21223.482 | P6: =N6+O6 -> 68294.25
C7: Loan period in years | D7: 20 | M7: =M6+1 -> 2027 | N7: =SUMPRODUCT(($M7=YEAR($C$17:$C$256))*$F$17:$F$256) -> 48020.861 | O7: =SUMPRODUCT(($M7=YEAR($C$17:$C$256))*$H$17:$H$256) -> 20273.389 | P7: =N7+O7 -> 68294.25
C8: Start date of loan | D8: 45658 | M8: =M7+1 -> 2028 | N8: =SUMPRODUCT(($M8=YEAR($C$17:$C$256))*$F$17:$F$256) -> 48990.131 | O8: =SUMPRODUCT(($M8=YEAR($C$17:$C$256))*$H$17:$H$256) -> 19304.119 | P8: =N8+O8 -> 68294.25
M9: =M8+1 -> 2029 | N9: =SUMPRODUCT(($M9=YEAR($C$17:$C$256))*$F$17:$F$256) -> 49978.966 | O9: =SUMPRODUCT(($M9=YEAR($C$17:$C$256))*$H$17:$H$256) -> 18315.285 | P9: =N9+O9 -> 68294.25
B10: Loan summary | M10: =M9+1 -> 2030 | N10: =SUMPRODUCT(($M10=YEAR($C$17:$C$256))*$F$17:$F$256) -> 50987.759 | O10: =SUMPRODUCT(($M10=YEAR($C$17:$C$256))*$H$17:$H$256) -> 17306.491 | P10: =N10+O10 -> 68294.25
C11: Monthly payment | D11: =IFERROR(IF(LoanIsGood,MonthlyPayment,""), "") -> 5691.1875 | M11: =M10+1 -> 2031 | N11: =SUMPRODUCT(($M11=YEAR($C$17:$C$256))*$F$17:$F$256) -> 52016.914 | O11: =SUMPRODUCT(($M11=YEAR($C$17:$C$256))*$H$17:$H$256) -> 16277.336 | P11: =N11+O11 -> 68294.25
C12: Number of payments | D12: =IFERROR(IF(LoanIsGood,LoanYears*12,""), "") -> 240 | M12: =M11+1 -> 2032 | N12: =SUMPRODUCT(($M12=YEAR($C$17:$C$256))*$F$17:$F$256) -> 53066.842 | O12: =SUMPRODUCT(($M12=YEAR($C$17:$C$256))*$H$17:$H$256) -> 15227.408 | P12: =N12+O12 -> 68294.25
C13: Total interest | D13: =IFERROR(IF(LoanIsGood,TotalLoanCost-LoanAmount,""), "") -> 240885 | M13: =M12+1 -> 2033 | N13: =SUMPRODUCT(($M13=YEAR($C$17:$C$256))*$F$17:$F$256) -> 54137.962 | O13: =SUMPRODUCT(($M13=YEAR($C$17:$C$256))*$H$17:$H$256) -> 14156.288 | P13: =N13+O13 -> 68294.25
C14: Total cost of loan | D14: =IFERROR(IF(LoanIsGood,MonthlyPayment*NumberOfPayments,""), "") -> 1365885 | M14: =M13+1 -> 2034 | N14: =SUMPRODUCT(($M14=YEAR($C$17:$C$256))*$F$17:$F$256) -> 55230.702 | O14: =SUMPRODUCT(($M14=YEAR($C$17:$C$256))*$H$17:$H$256) -> 13063.549 | P14: =N14+O14 -> 68294.25
C15: Outstanding balance (today) | D15: =IFERROR(LOOKUP(2,1/($C$17:$C$256<=TODAY()),$J$17:$J$256),D5) -> 1055326.8 | M15: =M14+1 -> 2035 | N15: =SUMPRODUCT(($M15=YEAR($C$17:$C$256))*$F$17:$F$256) -> 56345.498 | O15: =SUMPRODUCT(($M15=YEAR($C$17:$C$256))*$H$17:$H$256) -> 11948.752 | P15: =N15+O15 -> 68294.25
B16: Pmt no. | C16: Payment date | D16: Beginning balance | E16: Payment | F16: Principal | G16: Cumulative Principal | H16: Interest | I16: Cumulative Interest | J16: Ending balance | M16: =M15+1 -> 2036 | N16: =SUMPRODUCT(($M16=YEAR($C$17:$C$256))*$F$17:$F$256) -> 57482.795 | O16: =SUMPRODUCT(($M16=YEAR($C$17:$C$256))*$H$17:$H$256) -> 10811.455 | P16: =N16+O16 -> 68294.25
B17: =IFERROR(IF(LoanIsNotPaid*LoanIsGood,PaymentNumber,""), "") -> 1 | C17: =IFERROR(IF(LoanIsNotPaid*LoanIsGood,PaymentDate,LoanStartDate), LoanStartDate) -> 45689 | D17: =IFERROR(IF(LoanIsNotPaid*LoanIsGood,LoanValue,""), "") -> 1125000 | E17: =IFERROR(IF(LoanIsNotPaid*LoanIsGood,MonthlyPayment,0), 0) -> 5691.1875 | F17: =IFERROR(IF(LoanIsNotPaid*LoanIsGood,Principal,0), 0) -> 3816.1875 | G17: =SUM($F$17:F17) -> 3816.1875 | H17: =IFERROR(IF(LoanIsNotPaid*LoanIsGood,InterestAmt,0), 0) -> 1875 | I17: =SUM($H$17:H17) -> 1875 | J17: =IFERROR(IF(LoanIsNotPaid*LoanIsGood,EndingBalance,0), 0) -> 1121183.8 | M17: =M16+1 -> 2037 | N17: =SUMPRODUCT(($M17=YEAR($C$17:$C$256))*$F$17:$F$256) -> 58643.049 | O17: =SUMPRODUCT(($M17=YEAR($C$17:$C$256))*$H$17:$H$256) -> 9651.2016 | P17: =N17+O17 -> 68294.25
B18: =IFERROR(IF(LoanIsNotPaid*LoanIsGood,PaymentNumber,""), "") -> 2 | C18: =IFERROR(IF(LoanIsNotPaid*LoanIsGood,PaymentDate,LoanStartDate), LoanStartDate) -> 45717 | D18: =IFERROR(IF(LoanIsNotPaid*LoanIsGood,LoanValue,""), "") -> 1121183.8 | E18: =IFERROR(IF(LoanIsNotPaid*LoanIsGood,MonthlyPayment,0), 0) -> 5691.1875 | F18: =IFERROR(IF(LoanIsNotPaid*LoanIsGood,Principal,0), 0) -> 3822.5478 | G18: =SUM($F$17:F18) -> 7638.7354 | H18: =IFERROR(IF(LoanIsNotPaid*LoanIsGood,InterestAmt,0), 0) -> 1868.6397 | I18: =SUM($H$17:H18) -> 3743.6397 | J18: =IFERROR(IF(LoanIsNotPaid*LoanIsGood,EndingBalance,0), 0) -> 1117361.3 | M18: =M17+1 -> 2038 | N18: =SUMPRODUCT(($M18=YEAR($C$17:$C$256))*$F$17:$F$256) -> 59826.721 | O18: =SUMPRODUCT(($M18=YEAR($C$17:$C$256))*$H$17:$H$256) -> 8467.5295 | P18: =N18+O18 -> 68294.25
B19: =IFERROR(IF(LoanIsNotPaid*LoanIsGood,PaymentNumber,""), "") -> 3 | C19: =IFERROR(IF(LoanIsNotPaid*LoanIsGood,PaymentDate,LoanStartDate), LoanStartDate) -> 45748 | D19: =IFERROR(IF(LoanIsNotPaid*LoanIsGood,LoanValue,""), "") -> 1117361.3 | E19: =IFERROR(IF(LoanIsNotPaid*LoanIsGood,MonthlyPayment,0), 0) -> 5691.1875 | F19: =IFERROR(IF(LoanIsNotPaid*LoanIsGood,Principal,0), 0) -> 3828.9187 | G19: =SUM($F$17:F19) -> 11467.654 | H19: =IFERROR(IF(LoanIsNotPaid*LoanIsGood,InterestAmt,0), 0) -> 1862.2688 | I19: =SUM($H$17:H19) -> 5605.9085 | J19: =IFERROR(IF(LoanIsNotPaid*LoanIsGood,EndingBalance,0), 0) -> 1113532.3 | M19: =M18+1 -> 2039 | N19: =SUMPRODUCT(($M19=YEAR($C$17:$C$256))*$F$17:$F$256) -> 61034.285 | O19: =SUMPRODUCT(($M19=YEAR($C$17:$C$256))*$H$17:$H$256) -> 7259.9657 | P19: =N19+O19 -> 68294.25
B20: =IFERROR(IF(LoanIsNotPaid*LoanIsGood,PaymentNumber,""), "") -> 4 | C20: =IFERROR(IF(LoanIsNotPaid*LoanIsGood,PaymentDate,LoanStartDate), LoanStartDate) -> 45778 | D20: =IFERROR(IF(LoanIsNotPaid*LoanIsGood,LoanValue,""), "") -> 1113532.3 | E20: =IFERROR(IF(LoanIsNotPaid*LoanIsGood,MonthlyPayment,0), 0) -> 5691.1875 | F20: =IFERROR(IF(LoanIsNotPaid*LoanIsGood,Principal,0), 0) -> 3835.3003 | G20: =SUM($F$17:F20) -> 15302.954 | H20: =IFERROR(IF(LoanIsNotPaid*LoanIsGood,InterestAmt,0), 0) -> 1855.8872 | I20: =SUM($H$17:H20) -> 7461.7957 | J20: =IFERROR(IF(LoanIsNotPaid*LoanIsGood,EndingBalance,0), 0) -> 1109697 | M20: =M19+1 -> 2040 | N20: =SUMPRODUCT(($M20=YEAR($C$17:$C$256))*$F$17:$F$256) -> 62266.222 | O20: =SUMPRODUCT(($M20=YEAR($C$17:$C$256))*$H$17:$H$256) -> 6028.028 | P20: =N20+O20 -> 68294.25
B21: =IFERROR(IF(LoanIsNotPaid*LoanIsGood,PaymentNumber,""), "") -> 5 | C21: =IFERROR(IF(LoanIsNotPaid*LoanIsGood,PaymentDate,LoanStartDate), LoanStartDate) -> 45809 | D21: =IFERROR(IF(LoanIsNotPaid*LoanIsGood,LoanValue,""), "") -> 1109697 | E21: =IFERROR(IF(LoanIsNotPaid*LoanIsGood,MonthlyPayment,0), 0) -> 5691.1875 | F21: =IFERROR(IF(LoanIsNotPaid*LoanIsGood,Principal,0), 0) -> 3841.6924 | G21: =SUM($F$17:F21) -> 19144.647 | H21: =IFERROR(IF(LoanIsNotPaid*LoanIsGood,InterestAmt,0), 0) -> 1849.4951 | I21: =SUM($H$17:H21) -> 9311.2908 | J21: =IFERROR(IF(LoanIsNotPaid*LoanIsGood,EndingBalance,0), 0) -> 1105855.4 | M21: =M20+1 -> 2041 | N21: =SUMPRODUCT(($M21=YEAR($C$17:$C$256))*$F$17:$F$256) -> 63523.026 | O21: =SUMPRODUCT(($M21=YEAR($C$17:$C$256))*$H$17:$H$256) -> 4771.2244 | P21: =N21+O21 -> 68294.25
B22: =IFERROR(IF(LoanIsNotPaid*LoanIsGood,PaymentNumber,""), "") -> 6 | C22: =IFERROR(IF(LoanIsNotPaid*LoanIsGood,PaymentDate,LoanStartDate), LoanStartDate) -> 45839 | D22: =IFERROR(IF(LoanIsNotPaid*LoanIsGood,LoanValue,""), "") -> 1105855.4 | E22: =IFERROR(IF(LoanIsNotPaid*LoanIsGood,MonthlyPayment,0), 0) -> 5691.1875 | F22: =IFERROR(IF(LoanIsNotPaid*LoanIsGood,Principal,0), 0) -> 3848.0953 | G22: =SUM($F$17:F22) -> 22992.742 | H22: =IFERROR(IF(LoanIsNotPaid*LoanIsGood,InterestAmt,0), 0) -> 1843.0923 | I22: =SUM($H$17:H22) -> 11154.383 | J22: =IFERROR(IF(LoanIsNotPaid*LoanIsGood,EndingBalance,0), 0) -> 1102007.3 | M22: =M21+1 -> 2042 | N22: =SUMPRODUCT(($M22=YEAR($C$17:$C$256))*$F$17:$F$256) -> 64805.197 | O22: =SUMPRODUCT(($M22=YEAR($C$17:$C$256))*$H$17:$H$256) -> 3489.053 | P22: =N22+O22 -> 68294.25
B23: =IFERROR(IF(LoanIsNotPaid*LoanIsGood,PaymentNumber,""), "") -> 7 | C23: =IFERROR(IF(LoanIsNotPaid*LoanIsGood,PaymentDate,LoanStartDate), LoanStartDate) -> 45870 | D23: =IFERROR(IF(LoanIsNotPaid*LoanIsGood,LoanValue,""), "") -> 1102007.3 | E23: =IFERROR(IF(LoanIsNotPaid*LoanIsGood,MonthlyPayment,0), 0) -> 5691.1875 | F23: =IFERROR(IF(LoanIsNotPaid*LoanIsGood,Principal,0), 0) -> 3854.5088 | G23: =SUM($F$17:F23) -> 26847.251 | H23: =IFERROR(IF(LoanIsNotPaid*LoanIsGood,InterestAmt,0), 0) -> 1836.6788 | I23: =SUM($H$17:H23) -> 12991.062 | J23: =IFERROR(IF(LoanIsNotPaid*LoanIsGood,EndingBalance,0), 0) -> 1098152.7 | M23: =M22+1 -> 2043 | N23: =SUMPRODUCT(($M23=YEAR($C$17:$C$256))*$F$17:$F$256) -> 66113.248 | O23: =SUMPRODUCT(($M23=YEAR($C$17:$C$256))*$H$17:$H$256) -> 2181.0019 | P23: =N23+O23 -> 68294.25
B24: =IFERROR(IF(LoanIsNotPaid*LoanIsGood,PaymentNumber,""), "") -> 8 | C24: =IFERROR(IF(LoanIsNotPaid*LoanIsGood,PaymentDate,LoanStartDate), LoanStartDate) -> 45901 | D24: =IFERROR(IF(LoanIsNotPaid*LoanIsGood,LoanValue,""), "") -> 1098152.7 | E24: =IFERROR(IF(LoanIsNotPaid*LoanIsGood,MonthlyPayment,0), 0) -> 5691.1875 | F24: =IFERROR(IF(LoanIsNotPaid*LoanIsGood,Principal,0), 0) -> 3860.9329 | G24: =SUM($F$17:F24) -> 30708.184 | H24: =IFERROR(IF(LoanIsNotPaid*LoanIsGood,InterestAmt,0), 0) -> 1830.2546 | I24: =SUM($H$17:H24) -> 14821.316 | J24: =IFERROR(IF(LoanIsNotPaid*LoanIsGood,EndingBalance,0), 0) -> 1094291.8 | M24: =M23+1 -> 2044 | N24: =SUMPRODUCT(($M24=YEAR($C$17:$C$256))*$F$17:$F$256) -> 67447.702 | O24: =SUMPRODUCT(($M24=YEAR($C$17:$C$256))*$H$17:$H$256) -> 846.54856 | P24: =N24+O24 -> 68294.25
B25: =IFERROR(IF(LoanIsNotPaid*LoanIsGood,PaymentNumber,""), "") -> 9 | C25: =IFERROR(IF(LoanIsNotPaid*LoanIsGood,PaymentDate,LoanStartDate), LoanStartDate) -> 45931 | D25: =IFERROR(IF(LoanIsNotPaid*LoanIsGood,LoanValue,""), "") -> 1094291.8 | E25: =IFERROR(IF(LoanIsNotPaid*LoanIsGood,MonthlyPayment,0), 0) -> 5691.1875 | F25: =IFERROR(IF(LoanIsNotPaid*LoanIsGood,Principal,0), 0) -> 3867.3678 | G25: =SUM($F$17:F25) -> 34575.552 | H25: =IFERROR(IF(LoanIsNotPaid*LoanIsGood,InterestAmt,0), 0) -> 1823.8197 | I25: =SUM($H$17:H25) -> 16645.136 | J25: =IFERROR(IF(LoanIsNotPaid*LoanIsGood,EndingBalance,0), 0) -> 1090424.4 | M25: =M24+1 -> 2045 | N25: =SUMPRODUCT(($M25=YEAR($C$17:$C$256))*$F$17:$F$256) -> 5681.718 | O25: =SUMPRODUCT(($M25=YEAR($C$17:$C$256))*$H$17:$H$256) -> 9.46953 | P25: =N25+O25 -> 5691.1875
B26: =IFERROR(IF(LoanIsNotPaid*LoanIsGood,PaymentNumber,""), "") -> 10 | C26: =IFERROR(IF(LoanIsNotPaid*LoanIsGood,PaymentDate,LoanStartDate), LoanStartDate) -> 45962 | D26: =IFERROR(IF(LoanIsNotPaid*LoanIsGood,LoanValue,""), "") -> 1090424.4 | E26: =IFERROR(IF(LoanIsNotPaid*LoanIsGood,MonthlyPayment,0), 0) -> 5691.1875 | F26: =IFERROR(IF(LoanIsNotPaid*LoanIsGood,Principal,0), 0) -> 3873.8134 | G26: =SUM($F$17:F26) -> 38449.365 | H26: =IFERROR(IF(LoanIsNotPaid*LoanIsGood,InterestAmt,0), 0) -> 1817.3741 | I26: =SUM($H$17:H26) -> 18462.51 | J26: =IFERROR(IF(LoanIsNotPaid*LoanIsGood,EndingBalance,0), 0) -> 1086550.6 | M26: =M25+1 -> 2046 | N26: =SUMPRODUCT(($M26=YEAR($C$17:$C$256))*$F$17:$F$256) -> 0 | O26: =SUMPRODUCT(($M26=YEAR($C$17:$C$256))*$H$17:$H$256) -> 0 | P26: =N26+O26 -> 0
B27: =IFERROR(IF(LoanIsNotPaid*LoanIsGood,PaymentNumber,""), "") -> 11 | C27: =IFERROR(IF(LoanIsNotPaid*LoanIsGood,PaymentDate,LoanStartDate), LoanStartDate) -> 45992 | D27: =IFERROR(IF(LoanIsNotPaid*LoanIsGood,LoanValue,""), "") -> 1086550.6 | E27: =IFERROR(IF(LoanIsNotPaid*LoanIsGood,MonthlyPayment,0), 0) -> 5691.1875 | F27: =IFERROR(IF(LoanIsNotPaid*LoanIsGood,Principal,0), 0) -> 3880.2698 | G27: =SUM($F$17:F27) -> 42329.635 | H27: =IFERROR(IF(LoanIsNotPaid*LoanIsGood,InterestAmt,0), 0) -> 1810.9177 | I27: =SUM($H$17:H27) -> 20273.428 | J27: =IFERROR(IF(LoanIsNotPaid*LoanIsGood,EndingBalance,0), 0) -> 1082670.4 | M27: =M26+1 -> 2047 | N27: =SUMPRODUCT(($M27=YEAR($C$17:$C$256))*$F$17:$F$256) -> 0 | O27: =SUMPRODUCT(($M27=YEAR($C$17:$C$256))*$H$17:$H$256) -> 0 | P27: =N27+O27 -> 0
B28: =IFERROR(IF(LoanIsNotPaid*LoanIsGood,PaymentNumber,""), "") -> 12 | C28: =IFERROR(IF(LoanIsNotPaid*LoanIsGood,PaymentDate,LoanStartDate), LoanStartDate) -> 46023 | D28: =IFERROR(IF(LoanIsNotPaid*LoanIsGood,LoanValue,""), "") -> 1082670.4 | E28: =IFERROR(IF(LoanIsNotPaid*LoanIsGood,MonthlyPayment,0), 0) -> 5691.1875 | F28: =IFERROR(IF(LoanIsNotPaid*LoanIsGood,Principal,0), 0) -> 3886.7369 | G28: =SUM($F$17:F28) -> 46216.372 | H28: =IFERROR(IF(LoanIsNotPaid*LoanIsGood,InterestAmt,0), 0) -> 1804.4506 | I28: =SUM($H$17:H28) -> 22077.878 | J28: =IFERROR(IF(LoanIsNotPaid*LoanIsGood,EndingBalance,0), 0) -> 1078783.6 | M28: =M27+1 -> 2048 | N28: =SUMPRODUCT(($M28=YEAR($C$17:$C$256))*$F$17:$F$256) -> 0 | O28: =SUMPRODUCT(($M28=YEAR($C$17:$C$256))*$H$17:$H$256) -> 0 | P28: =N28+O28 -> 0
B29: =IFERROR(IF(LoanIsNotPaid*LoanIsGood,PaymentNumber,""), "") -> 13 | C29: =IFERROR(IF(LoanIsNotPaid*LoanIsGood,PaymentDate,LoanStartDate), LoanStartDate) -> 46054 | D29: =IFERROR(IF(LoanIsNotPaid*LoanIsGood,LoanValue,""), "") -> 1078783.6 | E29: =IFERROR(IF(LoanIsNotPaid*LoanIsGood,MonthlyPayment,0), 0) -> 5691.1875 | F29: =IFERROR(IF(LoanIsNotPaid*LoanIsGood,Principal,0), 0) -> 3893.2148 | G29: =SUM($F$17:F29) -> 50109.587 | H29: =IFERROR(IF(LoanIsNotPaid*LoanIsGood,InterestAmt,0), 0) -> 1797.9727 | I29: =SUM($H$17:H29) -> 23875.851 | J29: =IFERROR(IF(LoanIsNotPaid*LoanIsGood,EndingBalance,0), 0) -> 1074890.4 | M29: =M28+1 -> 2049 | N29: =SUMPRODUCT(($M29=YEAR($C$17:$C$256))*$F$17:$F$256) -> 0 | O29: =SUMPRODUCT(($M29=YEAR($C$17:$C$256))*$H$17:$H$256) -> 0 | P29: =N29+O29 -> 0
B30: =IFERROR(IF(LoanIsNotPaid*LoanIsGood,PaymentNumber,""), "") -> 14 | C30: =IFERROR(IF(LoanIsNotPaid*LoanIsGood,PaymentDate,LoanStartDate), LoanStartDate) -> 46082 | D30: =IFERROR(IF(LoanIsNotPaid*LoanIsGood,LoanValue,""), "") -> 1074890.4 | E30: =IFERROR(IF(LoanIsNotPaid*LoanIsGood,MonthlyPayment,0), 0) -> 5691.1875 | F30: =IFERROR(IF(LoanIsNotPaid*LoanIsGood,Principal,0), 0) -> 3899.7035 | G30: =SUM($F$17:F30) -> 54009.29 | H30: =IFERROR(IF(LoanIsNotPaid*LoanIsGood,InterestAmt,0), 0) -> 1791.484 | I30: =SUM($H$17:H30) -> 25667.335 | J30: =IFERROR(IF(LoanIsNotPaid*LoanIsGood,EndingBalance,0), 0) -> 1070990.7
B31: =IFERROR(IF(LoanIsNotPaid*LoanIsGood,PaymentNumber,""), "") -> 15 | C31: =IFERROR(IF(LoanIsNotPaid*LoanIsGood,PaymentDate,LoanStartDate), LoanStartDate) -> 46113 | D31: =IFERROR(IF(LoanIsNotPaid*LoanIsGood,LoanValue,""), "") -> 1070990.7 | E31: =IFERROR(IF(LoanIsNotPaid*LoanIsGood,MonthlyPayment,0), 0) -> 5691.1875 | F31: =IFERROR(IF(LoanIsNotPaid*LoanIsGood,Principal,0), 0) -> 3906.203 | G31: =SUM($F$17:F31) -> 57915.493 | H31: =IFERROR(IF(LoanIsNotPaid*LoanIsGood,InterestAmt,0), 0) -> 1784.9845 | I31: =SUM($H$17:H31) -> 27452.32 | J31: =IFERROR(IF(LoanIsNotPaid*LoanIsGood,EndingBalance,0), 0) -> 1067084.5
B32: =IFERROR(IF(LoanIsNotPaid*LoanIsGood,PaymentNumber,""), "") -> 16 | C32: =IFERROR(IF(LoanIsNotPaid*LoanIsGood,PaymentDate,LoanStartDate), LoanStartDate) -> 46143 | D32: =IFERROR(IF(LoanIsNotPaid*LoanIsGood,LoanValue,""), "") -> 1067084.5 | E32: =IFERROR(IF(LoanIsNotPaid*LoanIsGood,MonthlyPayment,0), 0) -> 5691.1875 | F32: =IFERROR(IF(LoanIsNotPaid*LoanIsGood,Principal,0), 0) -> 3912.7133 | G32: =SUM($F$17:F32) -> 61828.206 | H32: =IFERROR(IF(LoanIsNotPaid*LoanIsGood,InterestAmt,0), 0) -> 1778.4742 | I32: =SUM($H$17:H32) -> 29230.794 | J32: =IFERROR(IF(LoanIsNotPaid*LoanIsGood,EndingBalance,0), 0) -> 1063171.8
B33: =IFERROR(IF(LoanIsNotPaid*LoanIsGood,PaymentNumber,""), "") -> 17 | C33: =IFERROR(IF(LoanIsNotPaid*LoanIsGood,PaymentDate,LoanStartDate), LoanStartDate) -> 46174 | D33: =IFERROR(IF(LoanIsNotPaid*LoanIsGood,LoanValue,""), "") -> 1063171.8 | E33: =IFERROR(IF(LoanIsNotPaid*LoanIsGood,MonthlyPayment,0), 0) -> 5691.1875 | F33: =IFERROR(IF(LoanIsNotPaid*LoanIsGood,Principal,0), 0) -> 3919.2345 | G33: =SUM($F$17:F33) -> 65747.441 | H33: =IFERROR(IF(LoanIsNotPaid*LoanIsGood,InterestAmt,0), 0) -> 1771.953 | I33: =SUM($H$17:H33) -> 31002.747 | J33: =IFERROR(IF(LoanIsNotPaid*LoanIsGood,EndingBalance,0), 0) -> 1059252.6
B34: =IFERROR(IF(LoanIsNotPaid*LoanIsGood,PaymentNumber,""), "") -> 18 | C34: =IFERROR(IF(LoanIsNotPaid*LoanIsGood,PaymentDate,LoanStartDate), LoanStartDate) -> 46204 | D34: =IFERROR(IF(LoanIsNotPaid*LoanIsGood,LoanValue,""), "") -> 1059252.6 | E34: =IFERROR(IF(LoanIsNotPaid*LoanIsGood,MonthlyPayment,0), 0) -> 5691.1875 | F34: =IFERROR(IF(LoanIsNotPaid*LoanIsGood,Principal,0), 0) -> 3925.7666 | G34: =SUM($F$17:F34) -> 69673.208 | H34: =IFERROR(IF(LoanIsNotPaid*LoanIsGood,InterestAmt,0), 0) -> 1765.4209 | I34: =SUM($H$17:H34) -> 32768.168 | J34: =IFERROR(IF(LoanIsNotPaid*LoanIsGood,EndingBalance,0), 0) -> 1055326.8
B35: =IFERROR(IF(LoanIsNotPaid*LoanIsGood,PaymentNumber,""), "") -> 19 | C35: =IFERROR(IF(LoanIsNotPaid*LoanIsGood,PaymentDate,LoanStartDate), LoanStartDate) -> 46235 | D35: =IFERROR(IF(LoanIsNotPaid*LoanIsGood,LoanValue,""), "") -> 1055326.8 | E35: =IFERROR(IF(LoanIsNotPaid*LoanIsGood,MonthlyPayment,0), 0) -> 5691.1875 | F35: =IFERROR(IF(LoanIsNotPaid*LoanIsGood,Principal,0), 0) -> 3932.3095 | G35: =SUM($F$17:F35) -> 73605.517 | H35: =IFERROR(IF(LoanIsNotPaid*LoanIsGood,InterestAmt,0), 0) -> 1758.878 | I35: =SUM($H$17:H35) -> 34527.046 | J35: =IFERROR(IF(LoanIsNotPaid*LoanIsGood,EndingBalance,0), 0) -> 1051394.5
B36: =IFERROR(IF(LoanIsNotPaid*LoanIsGood,PaymentNumber,""), "") -> 20 | C36: =IFERROR(IF(LoanIsNotPaid*LoanIsGood,PaymentDate,LoanStartDate), LoanStartDate) -> 46266 | D36: =IFERROR(IF(LoanIsNotPaid*LoanIsGood,LoanValue,""), "") -> 1051394.5 | E36: =IFERROR(IF(LoanIsNotPaid*LoanIsGood,MonthlyPayment,0), 0) -> 5691.1875 | F36: =IFERROR(IF(LoanIsNotPaid*LoanIsGood,Principal,0), 0) -> 3938.8634 | G36: =SUM($F$17:F36) -> 77544.38 | H36: =IFERROR(IF(LoanIsNotPaid*LoanIsGood,InterestAmt,0), 0) -> 1752.3241 | I36: =SUM($H$17:H36) -> 36279.37 | J36: =IFERROR(IF(LoanIsNotPaid*LoanIsGood,EndingBalance,0), 0) -> 1047455.6
B37: =IFERROR(IF(LoanIsNotPaid*LoanIsGood,PaymentNumber,""), "") -> 21 | C37: =IFERROR(IF(LoanIsNotPaid*LoanIsGood,PaymentDate,LoanStartDate), LoanStartDate) -> 46296 | D37: =IFERROR(IF(LoanIsNotPaid*LoanIsGood,LoanValue,""), "") -> 1047455.6 | E37: =IFERROR(IF(LoanIsNotPaid*LoanIsGood,MonthlyPayment,0), 0) -> 5691.1875 | F37: =IFERROR(IF(LoanIsNotPaid*LoanIsGood,Principal,0), 0) -> 3945.4282 | G37: =SUM($F$17:F37) -> 81489.809 | H37: =IFERROR(IF(LoanIsNotPaid*LoanIsGood,InterestAmt,0), 0) -> 1745.7594 | I37: =SUM($H$17:H37) -> 38025.129 | J37: =IFERROR(IF(LoanIsNotPaid*LoanIsGood,EndingBalance,0), 0) -> 1043510.2
B38: =IFERROR(IF(LoanIsNotPaid*LoanIsGood,PaymentNumber,""), "") -> 22 | C38: =IFERROR(IF(LoanIsNotPaid*LoanIsGood,PaymentDate,LoanStartDate), LoanStartDate) -> 46327 | D38: =IFERROR(IF(LoanIsNotPaid*LoanIsGood,LoanValue,""), "") -> 1043510.2 | E38: =IFERROR(IF(LoanIsNotPaid*LoanIsGood,MonthlyPayment,0), 0) -> 5691.1875 | F38: =IFERROR(IF(LoanIsNotPaid*LoanIsGood,Principal,0), 0) -> 3952.0039 | G38: =SUM($F$17:F38) -> 85441.812 | H38: =IFERROR(IF(LoanIsNotPaid*LoanIsGood,InterestAmt,0), 0) -> 1739.1837 | I38: =SUM($H$17:H38) -> 39764.313 | J38: =IFERROR(IF(LoanIsNotPaid*LoanIsGood,EndingBalance,0), 0) -> 1039558.2
B39: =IFERROR(IF(LoanIsNotPaid*LoanIsGood,PaymentNumber,""), "") -> 23 | C39: =IFERROR(IF(LoanIsNotPaid*LoanIsGood,PaymentDate,LoanStartDate), LoanStartDate) -> 46357 | D39: =IFERROR(IF(LoanIsNotPaid*LoanIsGood,LoanValue,""), "") -> 1039558.2 | E39: =IFERROR(IF(LoanIsNotPaid*LoanIsGood,MonthlyPayment,0), 0) -> 5691.1875 | F39: =IFERROR(IF(LoanIsNotPaid*LoanIsGood,Principal,0), 0) -> 3958.5905 | G39: =SUM($F$17:F39) -> 89400.403 | H39: =IFERROR(IF(LoanIsNotPaid*LoanIsGood,InterestAmt,0), 0) -> 1732.597 | I39: =SUM($H$17:H39) -> 41496.91 | J39: =IFERROR(IF(LoanIsNotPaid*LoanIsGood,EndingBalance,0), 0) -> 1035599.6
B40: =IFERROR(IF(LoanIsNotPaid*LoanIsGood,PaymentNumber,""), "") -> 24 | C40: =IFERROR(IF(LoanIsNotPaid*LoanIsGood,PaymentDate,LoanStartDate), LoanStartDate) -> 46388 | D40: =IFERROR(IF(LoanIsNotPaid*LoanIsGood,LoanValue,""), "") -> 1035599.6 | E40: =IFERROR(IF(LoanIsNotPaid*LoanIsGood,MonthlyPayment,0), 0) -> 5691.1875 | F40: =IFERROR(IF(LoanIsNotPaid*LoanIsGood,Principal,0), 0) -> 3965.1882 | G40: =SUM($F$17:F40) -> 93365.591 | H40: =IFERROR(IF(LoanIsNotPaid*LoanIsGood,InterestAmt,0), 0) -> 1725.9993 | I40: =SUM($H$17:H40) -> 43222.909 | J40: =IFERROR(IF(LoanIsNotPaid*LoanIsGood,EndingBalance,0), 0) -> 1031634.4
B41: =IFERROR(IF(LoanIsNotPaid*LoanIsGood,PaymentNumber,""), "") -> 25 | C41: =IFERROR(IF(LoanIsNotPaid*LoanIsGood,PaymentDate,LoanStartDate), LoanStartDate) -> 46419 | D41: =IFERROR(IF(LoanIsNotPaid*LoanIsGood,LoanValue,""), "") -> 1031634.4 | E41: =IFERROR(IF(LoanIsNotPaid*LoanIsGood,MonthlyPayment,0), 0) -> 5691.1875 | F41: =IFERROR(IF(LoanIsNotPaid*LoanIsGood,Principal,0), 0) -> 3971.7968 | G41: =SUM($F$17:F41) -> 97337.388 | H41: =IFERROR(IF(LoanIsNotPaid*LoanIsGood,InterestAmt,0), 0) -> 1719.3907 | I41: =SUM($H$17:H41) -> 44942.3 | J41: =IFERROR(IF(LoanIsNotPaid*LoanIsGood,EndingBalance,0), 0) -> 1027662.6
... B256: =IFERROR(IF(LoanIsNotPaid*LoanIsGood,PaymentNumber,""), "") -> 240 | C256: =IFERROR(IF(LoanIsNotPaid*LoanIsGood,PaymentDate,LoanStartDate), LoanStartDate) -> 52963 | D256: =IFERROR(IF(LoanIsNotPaid*LoanIsGood,LoanValue,""), "") -> 5681.718 | E256: =IFERROR(IF(LoanIsNotPaid*LoanIsGood,MonthlyPayment,0), 0) -> 5691.1875 | F256: =IFERROR(IF(LoanIsNotPaid*LoanIsGood,Principal,0), 0) -> 5681.718 | G256: =SUM($F$17:F256) -> 1125000 | H256: =IFERROR(IF(LoanIsNotPaid*LoanIsGood,InterestAmt,0), 0) -> 9.46953 | I256: =SUM($H$17:H256) -> 240885 | J256: =IFERROR(IF(LoanIsNotPaid*LoanIsGood,EndingBalance,0), 0) -> -5.6345016e-08

Sheet Retirement Plan
A1: Annual Inflation | B1: =Settings!B11 -> 0.025 | E1: (assumptions are set on the Settings tab)
A2: Current Asset linked to Balance Sheet Latest | B2: ='Balance Sheet'!E68 -> 1225984.7 | C2: ='Balance Sheet'!F68 -> 840274.33
A3: Annual Savings Rate | B3: =Settings!B8 -> 30000
A4: 3% Growth | B4: =Settings!B12 -> 0.03 | D4: PROPERTY (from Housing)
A5: 5% Growth | B5: =Settings!B13 -> 0.05 | D5: Home equity - your share | E5: =Housing!B22 -> 244570.26
A6: 8% Growth | B6: =Settings!B14 -> 0.08 | D6: Property value - your share | E6: =Housing!B20 -> 825000
A7: Dividend % | B7: =Settings!B15 -> 0.04 | D7: Outstanding mortgage - your share | E7: =Housing!B21 -> 580429.74
A9: Amount to reserve for HDB | B9: =Settings!B19 -> 330000
A10: Amount still in CPF @55 estimated | B10: ='Balance Sheet'!B53 -> 95000
A11: Amount still in CPF @65 estimated | B11: ='Balance Sheet'!B54+'Balance Sheet'!B55 -> 180000
A12: Current SRS Amount (disburse @62) | B12: ='Balance Sheet'!B27 -> 120000
A13: Insurance/Endowment projected maturity (from Insurance) | B13: =Insurance!B6 -> 237422
A14: Age | B14: Year | C14: Retirement Sum (inflated) | D14: Actual Assets (Dec) | E14: Actual Cash (Dec) | F14: Assets @3% | G14: Accessible @3% | H14: Dividends @3% | I14: Assets @5% | J14: Accessible @5% | K14: Dividends @5% | L14: Assets @8% | M14: Accessible @8% | N14: Dividends @8%
A15: =Settings!B5 -> 42 | B15: =Settings!B6 -> 2026 | C15: =Settings!B18 -> 60000 | D15: 1225000 | F15: =$B$2 -> 1225984.7 | G15: =MAX(0,$B$2-SUM($C$64:$C$66)) -> 373984.71 | H15: =G15*$B$7 -> 14959.388 | I15: =$B$2 -> 1225984.7 | J15: =MAX(0,$B$2-SUM($C$64:$C$66)) -> 373984.71 | K15: =J15*$B$7 -> 14959.388 | L15: =$B$2 -> 1225984.7 | M15: =MAX(0,$B$2-SUM($C$64:$C$66)) -> 373984.71 | N15: =M15*$B$7 -> 14959.388
A16: =A15+1 -> 43 | B16: =B15+1 -> 2027 | C16: =(1+$B$1)*C15 -> 61500 | F16: =(1+$B$4)*F15+IF($A16<=Settings!$B$7,$B$3,-$C16) -> 1292764.2 | G16: =(1+$B$4)*G15+IF($A16<=Settings!$B$7,$B$3,-$C16)+SUMIFS($E$64:$E$66,$A$64:$A$66,$A16) -> 415204.25 | H16: =G16*$B$7 -> 16608.17 | I16: =(1+$B$5)*I15+IF($A16<=Settings!$B$7,$B$3,-$C16) -> 1317283.9 | J16: =(1+$B$5)*J15+IF($A16<=Settings!$B$7,$B$3,-$C16)+SUMIFS($E$64:$E$66,$A$64:$A$66,$A16) -> 422683.94 | K16: =J16*$B$7 -> 16907.358 | L16: =(1+$B$6)*L15+IF($A16<=Settings!$B$7,$B$3,-$C16) -> 1354063.5 | M16: =(1+$B$6)*M15+IF($A16<=Settings!$B$7,$B$3,-$C16)+SUMIFS($E$64:$E$66,$A$64:$A$66,$A16) -> 433903.48 | N16: =M16*$B$7 -> 17356.139
A17: =A16+1 -> 44 | B17: =B16+1 -> 2028 | C17: =(1+$B$1)*C16 -> 63037.5 | F17: =(1+$B$4)*F16+IF($A17<=Settings!$B$7,$B$3,-$C17) -> 1361547.2 | G17: =(1+$B$4)*G16+IF($A17<=Settings!$B$7,$B$3,-$C17)+SUMIFS($E$64:$E$66,$A$64:$A$66,$A17) -> 457660.38 | H17: =G17*$B$7 -> 18306.415 | I17: =(1+$B$5)*I16+IF($A17<=Settings!$B$7,$B$3,-$C17) -> 1413148.1 | J17: =(1+$B$5)*J16+IF($A17<=Settings!$B$7,$B$3,-$C17)+SUMIFS($E$64:$E$66,$A$64:$A$66,$A17) -> 473818.14 | K17: =J17*$B$7 -> 18952.726 | L17: =(1+$B$6)*L16+IF($A17<=Settings!$B$7,$B$3,-$C17) -> 1492388.6 | M17: =(1+$B$6)*M16+IF($A17<=Settings!$B$7,$B$3,-$C17)+SUMIFS($E$64:$E$66,$A$64:$A$66,$A17) -> 498615.76 | N17: =M17*$B$7 -> 19944.631
A18: =A17+1 -> 45 | B18: =B17+1 -> 2029 | C18: =(1+$B$1)*C17 -> 64613.437 | F18: =(1+$B$4)*F17+IF($A18<=Settings!$B$7,$B$3,-$C18) -> 1432393.6 | G18: =(1+$B$4)*G17+IF($A18<=Settings!$B$7,$B$3,-$C18)+SUMIFS($E$64:$E$66,$A$64:$A$66,$A18) -> 501390.19 | H18: =G18*$B$7 -> 20055.607 | I18: =(1+$B$5)*I17+IF($A18<=Settings!$B$7,$B$3,-$C18) -> 1513805.5 | J18: =(1+$B$5)*J17+IF($A18<=Settings!$B$7,$B$3,-$C18)+SUMIFS($E$64:$E$66,$A$64:$A$66,$A18) -> 527509.05 | K18: =J18*$B$7 -> 21100.362 | L18: =(1+$B$6)*L17+IF($A18<=Settings!$B$7,$B$3,-$C18) -> 1641779.6 | M18: =(1+$B$6)*M17+IF($A18<=Settings!$B$7,$B$3,-$C18)+SUMIFS($E$64:$E$66,$A$64:$A$66,$A18) -> 568505.02 | N18: =M18*$B$7 -> 22740.201
A19: =A18+1 -> 46 | B19: =B18+1 -> 2030 | C19: =(1+$B$1)*C18 -> 66228.773 | F19: =(1+$B$4)*F18+IF($A19<=Settings!$B$7,$B$3,-$C19) -> 1505365.4 | G19: =(1+$B$4)*G18+IF($A19<=Settings!$B$7,$B$3,-$C19)+SUMIFS($E$64:$E$66,$A$64:$A$66,$A19) -> 546431.89 | H19: =G19*$B$7 -> 21857.276 | I19: =(1+$B$5)*I18+IF($A19<=Settings!$B$7,$B$3,-$C19) -> 1619495.8 | J19: =(1+$B$5)*J18+IF($A19<=Settings!$B$7,$B$3,-$C19)+SUMIFS($E$64:$E$66,$A$64:$A$66,$A19) -> 583884.5 | K19: =J19*$B$7 -> 23355.38 | L19: =(1+$B$6)*L18+IF($A19<=Settings!$B$7,$B$3,-$C19) -> 1803122 | M19: =(1+$B$6)*M18+IF($A19<=Settings!$B$7,$B$3,-$C19)+SUMIFS($E$64:$E$66,$A$64:$A$66,$A19) -> 643985.43 | N19: =M19*$B$7 -> 25759.417
A20: =A19+1 -> 47 | B20: =B19+1 -> 2031 | C20: =(1+$B$1)*C19 -> 67884.493 | F20: =(1+$B$4)*F19+IF($A20<=Settings!$B$7,$B$3,-$C20) -> 1580526.4 | G20: =(1+$B$4)*G19+IF($A20<=Settings!$B$7,$B$3,-$C20)+SUMIFS($E$64:$E$66,$A$64:$A$66,$A20) -> 592824.85 | H20: =G20*$B$7 -> 23712.994 | I20: =(1+$B$5)*I19+IF($A20<=Settings!$B$7,$B$3,-$C20) -> 1730470.6 | J20: =(1+$B$5)*J19+IF($A20<=Settings!$B$7,$B$3,-$C20)+SUMIFS($E$64:$E$66,$A$64:$A$66,$A20) -> 643078.72 | K20: =J20*$B$7 -> 25723.149 | L20: =(1+$B$6)*L19+IF($A20<=Settings!$B$7,$B$3,-$C20) -> 1977371.8 | M20: =(1+$B$6)*M19+IF($A20<=Settings!$B$7,$B$3,-$C20)+SUMIFS($E$64:$E$66,$A$64:$A$66,$A20) -> 725504.26 | N20: =M20*$B$7 -> 29020.17
A21: =A20+1 -> 48 | B21: =B20+1 -> 2032 | C21: =(1+$B$1)*C20 -> 69581.605 | F21: =(1+$B$4)*F20+IF($A21<=Settings!$B$7,$B$3,-$C21) -> 1657942.2 | G21: =(1+$B$4)*G20+IF($A21<=Settings!$B$7,$B$3,-$C21)+SUMIFS($E$64:$E$66,$A$64:$A$66,$A21) -> 640609.6 | H21: =G21*$B$7 -> 25624.384 | I21: =(1+$B$5)*I20+IF($A21<=Settings!$B$7,$B$3,-$C21) -> 1846994.1 | J21: =(1+$B$5)*J20+IF($A21<=Settings!$B$7,$B$3,-$C21)+SUMIFS($E$64:$E$66,$A$64:$A$66,$A21) -> 705232.66 | K21: =J21*$B$7 -> 28209.306 | L21: =(1+$B$6)*L20+IF($A21<=Settings!$B$7,$B$3,-$C21) -> 2165561.5 | M21: =(1+$B$6)*M20+IF($A21<=Settings!$B$7,$B$3,-$C21)+SUMIFS($E$64:$E$66,$A$64:$A$66,$A21) -> 813544.6 | N21: =M21*$B$7 -> 32541.784
A22: =A21+1 -> 49 | B22: =B21+1 -> 2033 | C22: =(1+$B$1)*C21 -> 71321.145 | F22: =(1+$B$4)*F21+IF($A22<=Settings!$B$7,$B$3,-$C22) -> 1737680.4 | G22: =(1+$B$4)*G21+IF($A22<=Settings!$B$7,$B$3,-$C22)+SUMIFS($E$64:$E$66,$A$64:$A$66,$A22) -> 689827.88 | H22: =G22*$B$7 -> 27593.115 | I22: =(1+$B$5)*I21+IF($A22<=Settings!$B$7,$B$3,-$C22) -> 1969343.9 | J22: =(1+$B$5)*J21+IF($A22<=Settings!$B$7,$B$3,-$C22)+SUMIFS($E$64:$E$66,$A$64:$A$66,$A22) -> 770494.29 | K22: =J22*$B$7 -> 30819.772 | L22: =(1+$B$6)*L21+IF($A22<=Settings!$B$7,$B$3,-$C22) -> 2368806.4 | M22: =(1+$B$6)*M21+IF($A22<=Settings!$B$7,$B$3,-$C22)+SUMIFS($E$64:$E$66,$A$64:$A$66,$A22) -> 908628.17 | N22: =M22*$B$7 -> 36345.127
A23: =A22+1 -> 50 | B23: =B22+1 -> 2034 | C23: =(1+$B$1)*C22 -> 73104.174 | F23: =(1+$B$4)*F22+IF($A23<=Settings!$B$7,$B$3,-$C23) -> 1819810.8 | G23: =(1+$B$4)*G22+IF($A23<=Settings!$B$7,$B$3,-$C23)+SUMIFS($E$64:$E$66,$A$64:$A$66,$A23) -> 740522.72 | H23: =G23*$B$7 -> 29620.909 | I23: =(1+$B$5)*I22+IF($A23<=Settings!$B$7,$B$3,-$C23) -> 2097811 | J23: =(1+$B$5)*J22+IF($A23<=Settings!$B$7,$B$3,-$C23)+SUMIFS($E$64:$E$66,$A$64:$A$66,$A23) -> 839019.01 | K23: =J23*$B$7 -> 33560.76 | L23: =(1+$B$6)*L22+IF($A23<=Settings!$B$7,$B$3,-$C23) -> 2588311 | M23: =(1+$B$6)*M22+IF($A23<=Settings!$B$7,$B$3,-$C23)+SUMIFS($E$64:$E$66,$A$64:$A$66,$A23) -> 1011318.4 | N23: =M23*$B$7 -> 40452.737
A24: =A23+1 -> 51 | B24: =B23+1 -> 2035 | C24: =(1+$B$1)*C23 -> 74931.778 | F24: =(1+$B$4)*F23+IF($A24<=Settings!$B$7,$B$3,-$C24) -> 1904405.2 | G24: =(1+$B$4)*G23+IF($A24<=Settings!$B$7,$B$3,-$C24)+SUMIFS($E$64:$E$66,$A$64:$A$66,$A24) -> 792738.4 | H24: =G24*$B$7 -> 31709.536 | I24: =(1+$B$5)*I23+IF($A24<=Settings!$B$7,$B$3,-$C24) -> 2232701.6 | J24: =(1+$B$5)*J23+IF($A24<=Settings!$B$7,$B$3,-$C24)+SUMIFS($E$64:$E$66,$A$64:$A$66,$A24) -> 910969.96 | K24: =J24*$B$7 -> 36438.798 | L24: =(1+$B$6)*L23+IF($A24<=Settings!$B$7,$B$3,-$C24) -> 2825375.8 | M24: =(1+$B$6)*M23+IF($A24<=Settings!$B$7,$B$3,-$C24)+SUMIFS($E$64:$E$66,$A$64:$A$66,$A24) -> 1122223.9 | N24: =M24*$B$7 -> 44888.956
A25: =A24+1 -> 52 | B25: =B24+1 -> 2036 | C25: =(1+$B$1)*C24 -> 76805.073 | F25: =(1+$B$4)*F24+IF($A25<=Settings!$B$7,$B$3,-$C25) -> 1991537.3 | G25: =(1+$B$4)*G24+IF($A25<=Settings!$B$7,$B$3,-$C25)+SUMIFS($E$64:$E$66,$A$64:$A$66,$A25) -> 846520.55 | H25: =G25*$B$7 -> 33860.822 | I25: =(1+$B$5)*I24+IF($A25<=Settings!$B$7,$B$3,-$C25) -> 2374336.7 | J25: =(1+$B$5)*J24+IF($A25<=Settings!$B$7,$B$3,-$C25)+SUMIFS($E$64:$E$66,$A$64:$A$66,$A25) -> 986518.46 | K25: =J25*$B$7 -> 39460.738 | L25: =(1+$B$6)*L24+IF($A25<=Settings!$B$7,$B$3,-$C25) -> 3081405.9 | M25: =(1+$B$6)*M24+IF($A25<=Settings!$B$7,$B$3,-$C25)+SUMIFS($E$64:$E$66,$A$64:$A$66,$A25) -> 1242001.8 | N25: =M25*$B$7 -> 49680.072
A26: =A25+1 -> 53 | B26: =B25+1 -> 2037 | C26: =(1+$B$1)*C25 -> 78725.199 | F26: =(1+$B$4)*F25+IF($A26<=Settings!$B$7,$B$3,-$C26) -> 2081283.4 | G26: =(1+$B$4)*G25+IF($A26<=Settings!$B$7,$B$3,-$C26)+SUMIFS($E$64:$E$66,$A$64:$A$66,$A26) -> 901916.17 | H26: =G26*$B$7 -> 36076.647 | I26: =(1+$B$5)*I25+IF($A26<=Settings!$B$7,$B$3,-$C26) -> 2523053.5 | J26: =(1+$B$5)*J25+IF($A26<=Settings!$B$7,$B$3,-$C26)+SUMIFS($E$64:$E$66,$A$64:$A$66,$A26) -> 1065844.4 | K26: =J26*$B$7 -> 42633.775 | L26: =(1+$B$6)*L25+IF($A26<=Settings!$B$7,$B$3,-$C26) -> 3357918.4 | M26: =(1+$B$6)*M25+IF($A26<=Settings!$B$7,$B$3,-$C26)+SUMIFS($E$64:$E$66,$A$64:$A$66,$A26) -> 1371362 | N26: =M26*$B$7 -> 54854.478
A27: =A26+1 -> 54 | B27: =B26+1 -> 2038 | C27: =(1+$B$1)*C26 -> 80693.329 | F27: =(1+$B$4)*F26+IF($A27<=Settings!$B$7,$B$3,-$C27) -> 2173721.9 | G27: =(1+$B$4)*G26+IF($A27<=Settings!$B$7,$B$3,-$C27)+SUMIFS($E$64:$E$66,$A$64:$A$66,$A27) -> 958973.65 | H27: =G27*$B$7 -> 38358.946 | I27: =(1+$B$5)*I26+IF($A27<=Settings!$B$7,$B$3,-$C27) -> 2679206.2 | J27: =(1+$B$5)*J26+IF($A27<=Settings!$B$7,$B$3,-$C27)+SUMIFS($E$64:$E$66,$A$64:$A$66,$A27) -> 1149136.6 | K27: =J27*$B$7 -> 45965.464 | L27: =(1+$B$6)*L26+IF($A27<=Settings!$B$7,$B$3,-$C27) -> 3656551.8 | M27: =(1+$B$6)*M26+IF($A27<=Settings!$B$7,$B$3,-$C27)+SUMIFS($E$64:$E$66,$A$64:$A$66,$A27) -> 1511070.9 | N27: =M27*$B$7 -> 60442.836
... A58: =A57+1 -> 85 | B58: =B57+1 -> 2069 | C58: =(1+$B$1)*C57 -> 173491.2 | F58: =(1+$B$4)*F57+IF($A58<=Settings!$B$7,$B$3,-$C58) -> 1239857.1 | G58: =(1+$B$4)*G57+IF($A58<=Settings!$B$7,$B$3,-$C58)+SUMIFS($E$64:$E$66,$A$64:$A$66,$A58) -> 1373931 | H58: =G58*$B$7 -> 54957.241 | I58: =(1+$B$5)*I57+IF($A58<=Settings!$B$7,$B$3,-$C58) -> 6969860.9 | J58: =(1+$B$5)*J57+IF($A58<=Settings!$B$7,$B$3,-$C58)+SUMIFS($E$64:$E$66,$A$64:$A$66,$A58) -> 5197408.5 | K58: =J58*$B$7 -> 207896.34 | L58: =(1+$B$6)*L57+IF($A58<=Settings!$B$7,$B$3,-$C58) -> 32535022 | M58: =(1+$B$6)*M57+IF($A58<=Settings!$B$7,$B$3,-$C58)+SUMIFS($E$64:$E$66,$A$64:$A$66,$A58) -> 19955283 | N58: =M58*$B$7 -> 798211.32
